Workbook

Sheet 2022 Data
A1: Rank | B1: Team Name | C1: Matches Played | D1: Wins | E1: Losses | F1: No Result | G1: Net Run Rate (NRR) | H1: Net Run Rate (NRR) | J1: Total Runs Scored | K1: overs faced | M1: Total Runs Conceded | N1: Overs bowled | O1: Points | P1: Win Percntage | Q1: Batting Runs per Over | R1: Bowling Runs per Over | S1: Normalised NRR | T1: Batting Strength | U1: Bowling Strength | V1: SDI | W1: Balanced Performance Consistensy
A2: 1 | B2: GT | C2: 14 | D2: 10 | E2: 4 | F2: 0 | G2: 0.316 | H2: =J2/K2 - M2/N2 -> 0.30826705 | I2: 2339/278.1 | J2: 2339 | K2: 278.1 | L2: 2216/273.5 | M2: 2216 | N2: 273.5 | O2: =D2*2 + F2*1 -> 20 | P2: =D2/C2 -> 0.71428571 | Q2: =J2/K2 -> 8.4106437 | R2: =M2/N2 -> 8.1023766 | S2: =(H2-MIN($H$2:$H$11))/(MAX($H$2:$H$11)-MIN($H$2:$H$11)) -> 1 | T2: =(Q2 - MIN($Q$2:$Q$11)) / (MAX($Q$2:$Q$11) - MIN($Q$2:$Q$11)) -> 0.41632766 | U2: =(MAX($R$2:$R$11) - R2) / (MAX($R$2:$R$11) - MIN($R$2:$R$11)) -> 1 | V2: =0.4*P2 + 0.25*S2 + 0.2*T2 + 0.15*U2 -> 0.76897982 | W2: =AVERAGE(T2,U2) -> 0.70816383
A3: 2 | B3: RR | C3: 14 | D3: 9 | E3: 5 | F3: 0 | G3: 0.298 | H3: =J3/K3 - M3/N3 -> 0.29163958 | I3: 2464/279.2 | J3: 2464 | K3: 279.2 | L3: 2351/275.5 | M3: 2351 | N3: 275.5 | O3: =D3*2 + F3*1 -> 18 | P3: =D3/C3 -> 0.64285714 | Q3: =J3/K3 -> 8.8252149 | R3: =M3/N3 -> 8.5335753 | S3: =(H3-MIN($H$2:$H$11))/(MAX($H$2:$H$11)-MIN($H$2:$H$11)) -> 0.98928042 | T3: =(Q3 - MIN($Q$2:$Q$11)) / (MAX($Q$2:$Q$11) - MIN($Q$2:$Q$11)) -> 1 | U3: =(MAX($R$2:$R$11) - R3) / (MAX($R$2:$R$11) - MIN($R$2:$R$11)) -> 0.66234419 | V3: =0.4*P3 + 0.25*S3 + 0.2*T3 + 0.15*U3 -> 0.80381459 | W3: =AVERAGE(T3,U3) -> 0.83117209
A4: 3 | B4: LSG | C4: 14 | D4: 9 | E4: 5 | F4: 0 | G4: 0.251 | H4: =J4/K4 - M4/N4 -> 0.24528043 | I4: 2355/279.1 | J4: 2355 | K4: 279.1 | L4: 2289/279.4 | M4: 2289 | N4: 279.4 | O4: =D4*2 + F4*1 -> 18 | P4: =D4/C4 -> 0.64285714 | Q4: =J4/K4 -> 8.4378359 | R4: =M4/N4 -> 8.1925555 | S4: =(H4-MIN($H$2:$H$11))/(MAX($H$2:$H$11)-MIN($H$2:$H$11)) -> 0.9593931 | T4: =(Q4 - MIN($Q$2:$Q$11)) / (MAX($Q$2:$Q$11) - MIN($Q$2:$Q$11)) -> 0.45461146 | U4: =(MAX($R$2:$R$11) - R4) / (MAX($R$2:$R$11) - MIN($R$2:$R$11)) -> 0.92938425 | V4: =0.4*P4 + 0.25*S4 + 0.2*T4 + 0.15*U4 -> 0.72732106 | W4: =AVERAGE(T4,U4) -> 0.69199786
A5: 4 | B5: RCB | C5: 14 | D5: 8 | E5: 6 | F5: 0 | G5: -0.253 | H5: =J5/K5 - M5/N5 -> -0.25137505 | I5: 2268/275.4 | J5: 2268 | K5: 275.4 | L5: 2260/266.3 | M5: 2260 | N5: 266.3 | O5: =D5*2 + F5*1 -> 16 | P5: =D5/C5 -> 0.57142857 | Q5: =J5/K5 -> 8.2352941 | R5: =M5/N5 -> 8.4866692 | S5: =(H5-MIN($H$2:$H$11))/(MAX($H$2:$H$11)-MIN($H$2:$H$11)) -> 0.63920387 | T5: =(Q5 - MIN($Q$2:$Q$11)) / (MAX($Q$2:$Q$11) - MIN($Q$2:$Q$11)) -> 0.16945412 | U5: =(MAX($R$2:$R$11) - R5) / (MAX($R$2:$R$11) - MIN($R$2:$R$11)) -> 0.69907466 | V5: =0.4*P5 + 0.25*S5 + 0.2*T5 + 0.15*U5 -> 0.52712442 | W5: =AVERAGE(T5,U5) -> 0.43426439
A6: 5 | B6: DC | C6: 14 | D6: 7 | E6: 7 | F6: 0 | G6: 0.204 | H6: =J6/K6 - M6/N6 -> 0.19392962 | I6: 2341/266.0 | J6: 2341 | K6: 266 | L6: 2397/278.5 | M6: 2397 | N6: 278.5 | O6: =D6*2 + F6*1 -> 14 | P6: =D6/C6 -> 0.5 | Q6: =J6/K6 -> 8.8007519 | R6: =M6/N6 -> 8.6068223 | S6: =(H6-MIN($H$2:$H$11))/(MAX($H$2:$H$11)-MIN($H$2:$H$11)) -> 0.9262877 | T6: =(Q6 - MIN($Q$2:$Q$11)) / (MAX($Q$2:$Q$11) - MIN($Q$2:$Q$11)) -> 0.96555866 | U6: =(MAX($R$2:$R$11) - R6) / (MAX($R$2:$R$11) - MIN($R$2:$R$11)) -> 0.6049872 | V6: =0.4*P6 + 0.25*S6 + 0.2*T6 + 0.15*U6 -> 0.71543174 | W6: =AVERAGE(T6,U6) -> 0.78527293
A7: 6 | B7: PBKS | C7: 14 | D7: 7 | E7: 7 | F7: 0 | G7: -0.126 | H7: =J7/K7 - M7/N7 -> 0.12158359 | I7: 2343/270.1 | J7: 2343 | K7: 270.1 | L7: 2252/263.3 | M7: 2252 | N7: 263.3 | O7: =D7*2 + F7*1 -> 14 | P7: =D7/C7 -> 0.5 | Q7: =J7/K7 -> 8.674565 | R7: =M7/N7 -> 8.5529814 | S7: =(H7-MIN($H$2:$H$11))/(MAX($H$2:$H$11)-MIN($H$2:$H$11)) -> 0.87964688 | T7: =(Q7 - MIN($Q$2:$Q$11)) / (MAX($Q$2:$Q$11) - MIN($Q$2:$Q$11)) -> 0.78790089 | U7: =(MAX($R$2:$R$11) - R7) / (MAX($R$2:$R$11) - MIN($R$2:$R$11)) -> 0.64714801 | V7: =0.4*P7 + 0.25*S7 + 0.2*T7 + 0.15*U7 -> 0.6745641 | W7: =AVERAGE(T7,U7) -> 0.71752445
A8: 7 | B8: KKR | C8: 14 | D8: 6 | E8: 8 | F8: 0 | G8: 0.146 | H8: =J8/K8 - M8/N8 -> 0.17965235 | I8: 2232/268.1 | J8: 2232 | K8: 268.1 | L8: 2249/276.1 | M8: 2249 | N8: 276.1 | O8: =D8*2 + F8*1 -> 12 | P8: =D8/C8 -> 0.42857143 | Q8: =J8/K8 -> 8.3252518 | R8: =M8/N8 -> 8.1455994 | S8: =(H8-MIN($H$2:$H$11))/(MAX($H$2:$H$11)-MIN($H$2:$H$11)) -> 0.91708328 | T8: =(Q8 - MIN($Q$2:$Q$11)) / (MAX($Q$2:$Q$11) - MIN($Q$2:$Q$11)) -> 0.29610495 | U8: =(MAX($R$2:$R$11) - R8) / (MAX($R$2:$R$11) - MIN($R$2:$R$11)) -> 0.9661538 | V8: =0.4*P8 + 0.25*S8 + 0.2*T8 + 0.15*U8 -> 0.60484345 | W8: =AVERAGE(T8,U8) -> 0.63112938
A9: 8 | B9: SRH | C9: 14 | D9: 6 | E9: 8 | F9: 0 | G9: -0.379 | H9: =J9/K9 - M9/N9 -> -0.43816681 | I9: 2197/263.3 | J9: 2197 | K9: 263.3 | L9: 2416/275.1 | M9: 2416 | N9: 275.1 | O9: =D9*2 + F9*1 -> 12 | P9: =D9/C9 -> 0.42857143 | Q9: =J9/K9 -> 8.3440942 | R9: =M9/N9 -> 8.782261 | S9: =(H9-MIN($H$2:$H$11))/(MAX($H$2:$H$11)-MIN($H$2:$H$11)) -> 0.51878093 | T9: =(Q9 - MIN($Q$2:$Q$11)) / (MAX($Q$2:$Q$11) - MIN($Q$2:$Q$11)) -> 0.32263308 | U9: =(MAX($R$2:$R$11) - R9) / (MAX($R$2:$R$11) - MIN($R$2:$R$11)) -> 0.4676076 | V9: =0.4*P9 + 0.25*S9 + 0.2*T9 + 0.15*U9 -> 0.43579156 | W9: =AVERAGE(T9,U9) -> 0.39512034
A10: 9 | B10: CSK | C10: 14 | D10: 4 | E10: 10 | F10: 0 | G10: -0.203 | H10: =J10/K10 - M10/N10 -> -1.2079843 | I10: 2288/280.0 | J10: 2288 | K10: 280 | L10: 2524/269.1 | M10: 2524 | N10: 269.1 | O10: =D10*2 + F10*1 -> 8 | P10: =D10/C10 -> 0.28571429 | Q10: =J10/K10 -> 8.1714286 | R10: =M10/N10 -> 9.3794129 | S10: =(H10-MIN($H$2:$H$11))/(MAX($H$2:$H$11)-MIN($H$2:$H$11)) -> 0.022486664 | T10: =(Q10 - MIN($Q$2:$Q$11)) / (MAX($Q$2:$Q$11) - MIN($Q$2:$Q$11)) -> 0.079538203 | U10: =(MAX($R$2:$R$11) - R10) / (MAX($R$2:$R$11) - MIN($R$2:$R$11)) -> 0 | V10: =0.4*P10 + 0.25*S10 + 0.2*T10 + 0.15*U10 -> 0.13581502 | W10: =AVERAGE(T10,U10) -> 0.039769101
A11: 10 | B11: MI | C11: 14 | D11: 4 | E11: 10 | F11: 0 | G11: -0.506 | H11: =J11/K11 - M11/N11 -> -1.2428641 | I11: 2217/273.2 | J11: 2217 | K11: 273.2 | L11: 2550/272.5 | M11: 2550 | N11: 272.5 | O11: =D11*2 + F11*1 -> 8 | P11: =D11/C11 -> 0.28571429 | Q11: =J11/K11 -> 8.1149341 | R11: =M11/N11 -> 9.3577982 | S11: =(H11-MIN($H$2:$H$11))/(MAX($H$2:$H$11)-MIN($H$2:$H$11)) -> 0 | T11: =(Q11 - MIN($Q$2:$Q$11)) / (MAX($Q$2:$Q$11) - MIN($Q$2:$Q$11)) -> 0 | U11: =(MAX($R$2:$R$11) - R11) / (MAX($R$2:$R$11) - MIN($R$2:$R$11)) -> 0.016925669 | V11: =0.4*P11 + 0.25*S11 + 0.2*T11 + 0.15*U11 -> 0.11682456 | W11: =AVERAGE(T11,U11) -> 0.0084628343
A13: Rankings
A15: Win Percentage Ranks | E15: NRR Ranks | M15: Batting Strength | Q15: Bowling Strength
A17: 1 | B17: =B2 -> GT | C17: =P2 -> 0.71428571 | E17: 1 | F17: =INDEX($B$2:$B$11, MATCH(LARGE($H$2:$H$11,ROW(A1)),$H$2:$H$11,0)) -> GT | H17: =INDEX($S$2:$S$11, MATCH(F17,$B$2:$B$11,0)) -> 1 | M17: 1 | N17: =INDEX($B$2:$B$11, MATCH(LARGE($T$2:$T$11,ROW(A1)),$T$2:$T$11,0)) -> RR | O17: =INDEX($T$2:$T$11, MATCH(N17,$B$2:$B$11,0)) -> 1 | Q17: 1 | R17: =INDEX($B$2:$B$11, MATCH(LARGE($U$2:$U$11,ROW(A1)),$U$2:$U$11,0)) -> GT | S17: =INDEX($U$2:$U$11, MATCH(R17,$B$2:$B$11,0)) -> 1
A18: 2 | B18: =B3 -> RR | C18: =P3 -> 0.64285714 | E18: 2 | F18: =INDEX($B$2:$B$11, MATCH(LARGE($H$2:$H$11,ROW(A2)),$H$2:$H$11,0)) -> RR | H18: =INDEX($S$2:$S$11, MATCH(F18,$B$2:$B$11,0)) -> 0.98928042 | M18: 2 | N18: =INDEX($B$2:$B$11, MATCH(LARGE($T$2:$T$11,ROW(A2)),$T$2:$T$11,0)) -> DC | O18: =INDEX($T$2:$T$11, MATCH(N18,$B$2:$B$11,0)) -> 0.96555866 | Q18: 2 | R18: =INDEX($B$2:$B$11, MATCH(LARGE($U$2:$U$11,ROW(A2)),$U$2:$U$11,0)) -> KKR | S18: =INDEX($U$2:$U$11, MATCH(R18,$B$2:$B$11,0)) -> 0.9661538
A19: 3 | B19: =B4 -> LSG | C19: =P4 -> 0.64285714 | E19: 3 | F19: =INDEX($B$2:$B$11, MATCH(LARGE($H$2:$H$11,ROW(A3)),$H$2:$H$11,0)) -> LSG | H19: =INDEX($S$2:$S$11, MATCH(F19,$B$2:$B$11,0)) -> 0.9593931 | M19: 3 | N19: =INDEX($B$2:$B$11, MATCH(LARGE($T$2:$T$11,ROW(A3)),$T$2:$T$11,0)) -> PBKS | O19: =INDEX($T$2:$T$11, MATCH(N19,$B$2:$B$11,0)) -> 0.78790089 | Q19: 3 | R19: =INDEX($B$2:$B$11, MATCH(LARGE($U$2:$U$11,ROW(A3)),$U$2:$U$11,0)) -> LSG | S19: =INDEX($U$2:$U$11, MATCH(R19,$B$2:$B$11,0)) -> 0.92938425
A20: 4 | B20: =B5 -> RCB | C20: =P5 -> 0.57142857 | E20: 4 | F20: =INDEX($B$2:$B$11, MATCH(LARGE($H$2:$H$11,ROW(A4)),$H$2:$H$11,0)) -> DC | H20: =INDEX($S$2:$S$11, MATCH(F20,$B$2:$B$11,0)) -> 0.9262877 | M20: 4 | N20: =INDEX($B$2:$B$11, MATCH(LARGE($T$2:$T$11,ROW(A4)),$T$2:$T$11,0)) -> LSG | O20: =INDEX($T$2:$T$11, MATCH(N20,$B$2:$B$11,0)) -> 0.45461146 | Q20: 4 | R20: =INDEX($B$2:$B$11, MATCH(LARGE($U$2:$U$11,ROW(A4)),$U$2:$U$11,0)) -> RCB | S20: =INDEX($U$2:$U$11, MATCH(R20,$B$2:$B$11,0)) -> 0.69907466
A21: 5 | B21: =B6 -> DC | C21: =P6 -> 0.5 | E21: 5 | F21: =INDEX($B$2:$B$11, MATCH(LARGE($H$2:$H$11,ROW(A5)),$H$2:$H$11,0)) -> KKR | H21: =INDEX($S$2:$S$11, MATCH(F21,$B$2:$B$11,0)) -> 0.91708328 | M21: 5 | N21: =INDEX($B$2:$B$11, MATCH(LARGE($T$2:$T$11,ROW(A5)),$T$2:$T$11,0)) -> GT | O21: =INDEX($T$2:$T$11, MATCH(N21,$B$2:$B$11,0)) -> 0.41632766 | Q21: 5 | R21: =INDEX($B$2:$B$11, MATCH(LARGE($U$2:$U$11,ROW(A5)),$U$2:$U$11,0)) -> RR | S21: =INDEX($U$2:$U$11, MATCH(R21,$B$2:$B$11,0)) -> 0.66234419
A22: 6 | B22: =B7 -> PBKS | C22: =P7 -> 0.5 | E22: 6 | F22: =INDEX($B$2:$B$11, MATCH(LARGE($H$2:$H$11,ROW(A6)),$H$2:$H$11,0)) -> PBKS | H22: =INDEX($S$2:$S$11, MATCH(F22,$B$2:$B$11,0)) -> 0.87964688 | M22: 6 | N22: =INDEX($B$2:$B$11, MATCH(LARGE($T$2:$T$11,ROW(A6)),$T$2:$T$11,0)) -> SRH | O22: =INDEX($T$2:$T$11, MATCH(N22,$B$2:$B$11,0)) -> 0.32263308 | Q22: 6 | R22: =INDEX($B$2:$B$11, MATCH(LARGE($U$2:$U$11,ROW(A6)),$U$2:$U$11,0)) -> PBKS | S22: =INDEX($U$2:$U$11, MATCH(R22,$B$2:$B$11,0)) -> 0.64714801
A23: 7 | B23: =B8 -> KKR | C23: =P8 -> 0.42857143 | E23: 7 | F23: =INDEX($B$2:$B$11, MATCH(LARGE($H$2:$H$11,ROW(A7)),$H$2:$H$11,0)) -> RCB | H23: =INDEX($S$2:$S$11, MATCH(F23,$B$2:$B$11,0)) -> 0.63920387 | M23: 7 | N23: =INDEX($B$2:$B$11, MATCH(LARGE($T$2:$T$11,ROW(A7)),$T$2:$T$11,0)) -> KKR | O23: =INDEX($T$2:$T$11, MATCH(N23,$B$2:$B$11,0)) -> 0.29610495 | Q23: 7 | R23: =INDEX($B$2:$B$11, MATCH(LARGE($U$2:$U$11,ROW(A7)),$U$2:$U$11,0)) -> DC | S23: =INDEX($U$2:$U$11, MATCH(R23,$B$2:$B$11,0)) -> 0.6049872
A24: 8 | B24: =B9 -> SRH | C24: =P9 -> 0.42857143 | E24: 8 | F24: =INDEX($B$2:$B$11, MATCH(LARGE($H$2:$H$11,ROW(A8)),$H$2:$H$11,0)) -> SRH | H24: =INDEX($S$2:$S$11, MATCH(F24,$B$2:$B$11,0)) -> 0.51878093 | M24: 8 | N24: =INDEX($B$2:$B$11, MATCH(LARGE($T$2:$T$11,ROW(A8)),$T$2:$T$11,0)) -> RCB | O24: =INDEX($T$2:$T$11, MATCH(N24,$B$2:$B$11,0)) -> 0.16945412 | Q24: 8 | R24: =INDEX($B$2:$B$11, MATCH(LARGE($U$2:$U$11,ROW(A8)),$U$2:$U$11,0)) -> SRH | S24: =INDEX($U$2:$U$11, MATCH(R24,$B$2:$B$11,0)) -> 0.4676076
A25: 9 | B25: =B10 -> CSK | C25: =P10 -> 0.28571429 | E25: 9 | F25: =INDEX($B$2:$B$11, MATCH(LARGE($H$2:$H$11,ROW(A9)),$H$2:$H$11,0)) -> CSK | H25: =INDEX($S$2:$S$11, MATCH(F25,$B$2:$B$11,0)) -> 0.022486664 | M25: 9 | N25: =INDEX($B$2:$B$11, MATCH(LARGE($T$2:$T$11,ROW(A9)),$T$2:$T$11,0)) -> CSK | O25: =INDEX($T$2:$T$11, MATCH(N25,$B$2:$B$11,0)) -> 0.079538203 | Q25: 9 | R25: =INDEX($B$2:$B$11, MATCH(LARGE($U$2:$U$11,ROW(A9)),$U$2:$U$11,0)) -> MI | S25: =INDEX($U$2:$U$11, MATCH(R25,$B$2:$B$11,0)) -> 0.016925669
A26: 10 | B26: =B11 -> MI | C26: =P11 -> 0.28571429 | E26: 10 | F26: =INDEX($B$2:$B$11, MATCH(LARGE($H$2:$H$11,ROW(A10)),$H$2:$H$11,0)) -> MI | H26: =INDEX($S$2:$S$11, MATCH(F26,$B$2:$B$11,0)) -> 0 | M26: 10 | N26: =INDEX($B$2:$B$11, MATCH(LARGE($T$2:$T$11,ROW(A10)),$T$2:$T$11,0)) -> MI | O26: =INDEX($T$2:$T$11, MATCH(N26,$B$2:$B$11,0)) -> 0 | Q26: 10 | R26: =INDEX($B$2:$B$11, MATCH(LARGE($U$2:$U$11,ROW(A10)),$U$2:$U$11,0)) -> CSK | S26: =INDEX($U$2:$U$11, MATCH(R26,$B$2:$B$11,0)) -> 0
C30: Season Dominance Index | M30: Balanced Performer Index
C32: 1 | D32: =INDEX($B$2:$B$11, MATCH(LARGE($V$2:$V$11,ROW(A1)),$V$2:$V$11,0)) -> RR | E32: =INDEX($V$2:$V$11, MATCH(D32,$B$2:$B$11,0)) -> 0.80381459 | M32: 1 | N32: =INDEX($B$2:$B$11, MATCH(LARGE($W$2:$W$11,ROW(A1)),$W$2:$W$11,0)) -> RR | O32: =INDEX($W$2:$W$11, MATCH(N32,$B$2:$B$11,0)) -> 0.83117209
C33: 2 | D33: =INDEX($B$2:$B$11, MATCH(LARGE($V$2:$V$11,ROW(A2)),$V$2:$V$11,0)) -> GT | E33: =INDEX($V$2:$V$11, MATCH(D33,$B$2:$B$11,0)) -> 0.76897982 | M33: 2 | N33: =INDEX($B$2:$B$11, MATCH(LARGE($W$2:$W$11,ROW(A2)),$W$2:$W$11,0)) -> DC | O33: =INDEX($W$2:$W$11, MATCH(N33,$B$2:$B$11,0)) -> 0.78527293
C34: 3 | D34: =INDEX($B$2:$B$11, MATCH(LARGE($V$2:$V$11,ROW(A3)),$V$2:$V$11,0)) -> LSG | E34: =INDEX($V$2:$V$11, MATCH(D34,$B$2:$B$11,0)) -> 0.72732106 | M34: 3 | N34: =INDEX($B$2:$B$11, MATCH(LARGE($W$2:$W$11,ROW(A3)),$W$2:$W$11,0)) -> PBKS | O34: =INDEX($W$2:$W$11, MATCH(N34,$B$2:$B$11,0)) -> 0.71752445
C35: 4 | D35: =INDEX($B$2:$B$11, MATCH(LARGE($V$2:$V$11,ROW(A4)),$V$2:$V$11,0)) -> DC | E35: =INDEX($V$2:$V$11, MATCH(D35,$B$2:$B$11,0)) -> 0.71543174 | M35: 4 | N35: =INDEX($B$2:$B$11, MATCH(LARGE($W$2:$W$11,ROW(A4)),$W$2:$W$11,0)) -> GT | O35: =INDEX($W$2:$W$11, MATCH(N35,$B$2:$B$11,0)) -> 0.70816383
C36: 5 | D36: =INDEX($B$2:$B$11, MATCH(LARGE($V$2:$V$11,ROW(A5)),$V$2:$V$11,0)) -> PBKS | E36: =INDEX($V$2:$V$11, MATCH(D36,$B$2:$B$11,0)) -> 0.6745641 | M36: 5 | N36: =INDEX($B$2:$B$11, MATCH(LARGE($W$2:$W$11,ROW(A5)),$W$2:$W$11,0)) -> LSG | O36: =INDEX($W$2:$W$11, MATCH(N36,$B$2:$B$11,0)) -> 0.69199786
C37: 6 | D37: =INDEX($B$2:$B$11, MATCH(LARGE($V$2:$V$11,ROW(A6)),$V$2:$V$11,0)) -> KKR | E37: =INDEX($V$2:$V$11, MATCH(D37,$B$2:$B$11,0)) -> 0.60484345 | M37: 6 | N37: =INDEX($B$2:$B$11, MATCH(LARGE($W$2:$W$11,ROW(A6)),$W$2:$W$11,0)) -> KKR | O37: =INDEX($W$2:$W$11, MATCH(N37,$B$2:$B$11,0)) -> 0.63112938
C38: 7 | D38: =INDEX($B$2:$B$11, MATCH(LARGE($V$2:$V$11,ROW(A7)),$V$2:$V$11,0)) -> RCB | E38: =INDEX($V$2:$V$11, MATCH(D38,$B$2:$B$11,0)) -> 0.52712442 | M38: 7 | N38: =INDEX($B$2:$B$11, MATCH(LARGE($W$2:$W$11,ROW(A7)),$W$2:$W$11,0)) -> RCB | O38: =INDEX($W$2:$W$11, MATCH(N38,$B$2:$B$11,0)) -> 0.43426439
C39: 8 | D39: =INDEX($B$2:$B$11, MATCH(LARGE($V$2:$V$11,ROW(A8)),$V$2:$V$11,0)) -> SRH | E39: =INDEX($V$2:$V$11, MATCH(D39,$B$2:$B$11,0)) -> 0.43579156 | M39: 8 | N39: =INDEX($B$2:$B$11, MATCH(LARGE($W$2:$W$11,ROW(A8)),$W$2:$W$11,0)) -> SRH | O39: =INDEX($W$2:$W$11, MATCH(N39,$B$2:$B$11,0)) -> 0.39512034
C40: 9 | D40: =INDEX($B$2:$B$11, MATCH(LARGE($V$2:$V$11,ROW(A9)),$V$2:$V$11,0)) -> CSK | E40: =INDEX($V$2:$V$11, MATCH(D40,$B$2:$B$11,0)) -> 0.13581502 | M40: 9 | N40: =INDEX($B$2:$B$11, MATCH(LARGE($W$2:$W$11,ROW(A9)),$W$2:$W$11,0)) -> CSK | O40: =INDEX($W$2:$W$11, MATCH(N40,$B$2:$B$11,0)) -> 0.039769101
C41: 10 | D41: =INDEX($B$2:$B$11, MATCH(LARGE($V$2:$V$11,ROW(A10)),$V$2:$V$11,0)) -> MI | E41: =INDEX($V$2:$V$11, MATCH(D41,$B$2:$B$11,0)) -> 0.11682456 | M41: 10 | N41: =INDEX($B$2:$B$11, MATCH(LARGE($W$2:$W$11,ROW(A10)),$W$2:$W$11,0)) -> MI | O41: =INDEX($W$2:$W$11, MATCH(N41,$B$2:$B$11,0)) -> 0.0084628343
C76: =INDEX(O$32:O$41,MATCH(D32,N$32:N$41,0)) -> 0.83117209
C77: =INDEX(O$32:O$41,MATCH(D33,N$32:N$41,0)) -> 0.70816383
C78: =INDEX(O$32:O$41,MATCH(D34,N$32:N$41,0)) -> 0.69199786
C79: =INDEX(O$32:O$41,MATCH(D35,N$32:N$41,0)) -> 0.78527293
C80: =INDEX(O$32:O$41,MATCH(D36,N$32:N$41,0)) -> 0.71752445
C81: =INDEX(O$32:O$41,MATCH(D37,N$32:N$41,0)) -> 0.63112938
...

Sheet 2023 Data
A1: Rank | B1: Team Name | C1: Matches Played | D1: Wins | E1: Losses | F1: No Result | G1: Net Run Rate (NRR) | H1: Net Run Rate (NRR) | J1: Total Runs Scored | K1: overs faced | L1: Total Runs Conceded | M1: Total Runs Conceded | N1: Overs bowled | O1: Points | P1: Win Percntage | Q1: Batting Runs per Over | R1: Bowling Runs per Over | S1: Normalised NRR | T1: Batting Strength | U1: Bowling Strength | V1: SDI | W1: Balanced Performance Consistensy
A2: 1 | B2: GT | C2: 14 | D2: 10 | E2: 4 | F2: 0 | G2: 0.809 | H2: =J2/K2 - M2/N2 -> 0.80743564 | I2: 2450/268.1 | J2: 2450 | K2: 268.1 | L2: 2326/279.2 | M2: 2326 | N2: 279.2 | O2: =D2*2 + F2*1 -> 20 | P2: =D2/C2 -> 0.71428571 | Q2: =J2/K2 -> 9.1383812 | R2: =M2/N2 -> 8.3309456 | S2: =(H2-MIN($H$2:$H$11))/(MAX($H$2:$H$11)-MIN($H$2:$H$11)) -> 1 | T2: =(Q2 - MIN($Q$2:$Q$11)) / (MAX($Q$2:$Q$11) - MIN($Q$2:$Q$11)) -> 0.73213478 | U2: =(MAX($R$2:$R$11) - R2) / (MAX($R$2:$R$11) - MIN($R$2:$R$11)) -> 1 | V2: =0.4*P2 + 0.25*S2 + 0.2*T2 + 0.15*U2 -> 0.83214124 | W2: =AVERAGE(T2,U2) -> 0.86606739
A3: 2 | B3: CSK | C3: 14 | D3: 8 | E3: 5 | F3: 1 | G3: 0.652 | H3: =J3/K3 - M3/N3 -> 0.64780761 | I3: 2369/254.3 | J3: 2369 | K3: 254.3 | L3: 2232/257.5 | M3: 2232 | N3: 257.5 | O3: =D3*2 + F3*1 -> 17 | P3: =D3/C3 -> 0.57142857 | Q3: =J3/K3 -> 9.3157688 | R3: =M3/N3 -> 8.6679612 | S3: =(H3-MIN($H$2:$H$11))/(MAX($H$2:$H$11)-MIN($H$2:$H$11)) -> 0.90133797 | T3: =(Q3 - MIN($Q$2:$Q$11)) / (MAX($Q$2:$Q$11) - MIN($Q$2:$Q$11)) -> 0.8375001 | U3: =(MAX($R$2:$R$11) - R3) / (MAX($R$2:$R$11) - MIN($R$2:$R$11)) -> 0.74033124 | V3: =0.4*P3 + 0.25*S3 + 0.2*T3 + 0.15*U3 -> 0.73245563 | W3: =AVERAGE(T3,U3) -> 0.78891567
A4: 3 | B4: LSG | C4: 14 | D4: 8 | E4: 5 | F4: 1 | G4: 0.284 | H4: =J4/K4 - M4/N4 -> 0.28228429 | I4: 2253/255.2 | J4: 2253 | K4: 255.2 | L4: 2216/259.3 | M4: 2216 | N4: 259.3 | O4: =D4*2 + F4*1 -> 17 | P4: =D4/C4 -> 0.57142857 | Q4: =J4/K4 -> 8.8283699 | R4: =M4/N4 -> 8.5460856 | S4: =(H4-MIN($H$2:$H$11))/(MAX($H$2:$H$11)-MIN($H$2:$H$11)) -> 0.67541728 | T4: =(Q4 - MIN($Q$2:$Q$11)) / (MAX($Q$2:$Q$11) - MIN($Q$2:$Q$11)) -> 0.54799315 | U4: =(MAX($R$2:$R$11) - R4) / (MAX($R$2:$R$11) - MIN($R$2:$R$11)) -> 0.83423572 | V4: =0.4*P4 + 0.25*S4 + 0.2*T4 + 0.15*U4 -> 0.63215974 | W4: =AVERAGE(T4,U4) -> 0.69111443
A5: 4 | B5: MI | C5: 14 | D5: 8 | E5: 6 | F5: 0 | G5: -0.044 | H5: =J5/K5 - M5/N5 -> -0.039467764 | I5: 2592/270.3 | J5: 2592 | K5: 270.3 | L5: 2620/272.1 | M5: 2620 | N5: 272.1 | O5: =D5*2 + F5*1 -> 16 | P5: =D5/C5 -> 0.57142857 | Q5: =J5/K5 -> 9.5893452 | R5: =M5/N5 -> 9.6288129 | S5: =(H5-MIN($H$2:$H$11))/(MAX($H$2:$H$11)-MIN($H$2:$H$11)) -> 0.47655051 | T5: =(Q5 - MIN($Q$2:$Q$11)) / (MAX($Q$2:$Q$11) - MIN($Q$2:$Q$11)) -> 1 | U5: =(MAX($R$2:$R$11) - R5) / (MAX($R$2:$R$11) - MIN($R$2:$R$11)) -> 0 | V5: =0.4*P5 + 0.25*S5 + 0.2*T5 + 0.15*U5 -> 0.54770906 | W5: =AVERAGE(T5,U5) -> 0.5
A6: 5 | B6: RR | C6: 14 | D6: 7 | E6: 7 | F6: 0 | G6: 0.148 | H6: =J6/K6 - M6/N6 -> 0.14560441 | I6: 2419/272.1 | J6: 2419 | K6: 272.1 | L6: 2389/273.2 | M6: 2389 | N6: 273.2 | O6: =D6*2 + F6*1 -> 14 | P6: =D6/C6 -> 0.5 | Q6: =J6/K6 -> 8.8901139 | R6: =M6/N6 -> 8.7445095 | S6: =(H6-MIN($H$2:$H$11))/(MAX($H$2:$H$11)-MIN($H$2:$H$11)) -> 0.59093892 | T6: =(Q6 - MIN($Q$2:$Q$11)) / (MAX($Q$2:$Q$11) - MIN($Q$2:$Q$11)) -> 0.58466809 | U6: =(MAX($R$2:$R$11) - R6) / (MAX($R$2:$R$11) - MIN($R$2:$R$11)) -> 0.68135114 | V6: =0.4*P6 + 0.25*S6 + 0.2*T6 + 0.15*U6 -> 0.56687102 | W6: =AVERAGE(T6,U6) -> 0.63300961
A7: 6 | B7: RCB | C7: 14 | D7: 7 | E7: 7 | F7: 0 | G7: 0.135 | H7: =J7/K7 - M7/N7 -> 0.13933911 | I7: 2502/275.4 | J7: 2502 | K7: 275.4 | L7: 2435/272.2 | M7: 2435 | N7: 272.2 | O7: =D7*2 + F7*1 -> 14 | P7: =D7/C7 -> 0.5 | Q7: =J7/K7 -> 9.0849673 | R7: =M7/N7 -> 8.9456282 | S7: =(H7-MIN($H$2:$H$11))/(MAX($H$2:$H$11)-MIN($H$2:$H$11)) -> 0.58706649 | T7: =(Q7 - MIN($Q$2:$Q$11)) / (MAX($Q$2:$Q$11) - MIN($Q$2:$Q$11)) -> 0.70040781 | U7: =(MAX($R$2:$R$11) - R7) / (MAX($R$2:$R$11) - MIN($R$2:$R$11)) -> 0.52639024 | V7: =0.4*P7 + 0.25*S7 + 0.2*T7 + 0.15*U7 -> 0.56580672 | W7: =AVERAGE(T7,U7) -> 0.61339903
A8: 7 | B8: KKR | C8: 14 | D8: 6 | E8: 8 | F8: 0 | G8: -0.239 | H8: =J8/K8 - M8/N8 -> -0.23290138 | I8: 2463/274.3 | J8: 2463 | K8: 274.3 | L8: 2432/264.0 | M8: 2432 | N8: 264 | O8: =D8*2 + F8*1 -> 12 | P8: =D8/C8 -> 0.42857143 | Q8: =J8/K8 -> 8.9792198 | R8: =M8/N8 -> 9.2121212 | S8: =(H8-MIN($H$2:$H$11))/(MAX($H$2:$H$11)-MIN($H$2:$H$11)) -> 0.3569941 | T8: =(Q8 - MIN($Q$2:$Q$11)) / (MAX($Q$2:$Q$11) - MIN($Q$2:$Q$11)) -> 0.63759553 | U8: =(MAX($R$2:$R$11) - R8) / (MAX($R$2:$R$11) - MIN($R$2:$R$11)) -> 0.32105879 | V8: =0.4*P8 + 0.25*S8 + 0.2*T8 + 0.15*U8 -> 0.43635502 | W8: =AVERAGE(T8,U8) -> 0.47932716
A9: 8 | B9: PBKS | C9: 14 | D9: 6 | E9: 8 | F9: 0 | G9: -0.304 | H9: =J9/K9 - M9/N9 -> -0.30440672 | I9: 2518/275.3 | J9: 2518 | K9: 275.3 | L9: 2564/271.3 | M9: 2564 | N9: 271.3 | O9: =D9*2 + F9*1 -> 12 | P9: =D9/C9 -> 0.42857143 | Q9: =J9/K9 -> 9.1463858 | R9: =M9/N9 -> 9.4507925 | S9: =(H9-MIN($H$2:$H$11))/(MAX($H$2:$H$11)-MIN($H$2:$H$11)) -> 0.31279846 | T9: =(Q9 - MIN($Q$2:$Q$11)) / (MAX($Q$2:$Q$11) - MIN($Q$2:$Q$11)) -> 0.73688936 | U9: =(MAX($R$2:$R$11) - R9) / (MAX($R$2:$R$11) - MIN($R$2:$R$11)) -> 0.13716383 | V9: =0.4*P9 + 0.25*S9 + 0.2*T9 + 0.15*U9 -> 0.41758063 | W9: =AVERAGE(T9,U9) -> 0.43702659
A10: 9 | B10: DC | C10: 14 | D10: 5 | E10: 9 | F10: 0 | G10: -0.808 | H10: =J10/K10 - M10/N10 -> -0.810492 | I10: 2182/276.0 | J10: 2182 | K10: 276 | L10: 2424/278.1 | M10: 2424 | N10: 278.1 | O10: =D10*2 + F10*1 -> 10 | P10: =D10/C10 -> 0.35714286 | Q10: =J10/K10 -> 7.9057971 | R10: =M10/N10 -> 8.7162891 | S10: =(H10-MIN($H$2:$H$11))/(MAX($H$2:$H$11)-MIN($H$2:$H$11)) -> 0 | T10: =(Q10 - MIN($Q$2:$Q$11)) / (MAX($Q$2:$Q$11) - MIN($Q$2:$Q$11)) -> 0 | U10: =(MAX($R$2:$R$11) - R10) / (MAX($R$2:$R$11) - MIN($R$2:$R$11)) -> 0.70309482 | V10: =0.4*P10 + 0.25*S10 + 0.2*T10 + 0.15*U10 -> 0.24832137 | W10: =AVERAGE(T10,U10) -> 0.35154741
A11: 10 | B11: SRH | C11: 14 | D11: 4 | E11: 10 | F11: 0 | G11: -0.59 | H11: =J11/K11 - M11/N11 -> -0.59214483 | I11: 2376/277.1 | J11: 2376 | K11: 277.1 | L11: 2486/271.2 | M11: 2486 | N11: 271.2 | O11: =D11*2 + F11*1 -> 8 | P11: =D11/C11 -> 0.28571429 | Q11: =J11/K11 -> 8.5745218 | R11: =M11/N11 -> 9.1666667 | S11: =(H11-MIN($H$2:$H$11))/(MAX($H$2:$H$11)-MIN($H$2:$H$11)) -> 0.13495484 | T11: =(Q11 - MIN($Q$2:$Q$11)) / (MAX($Q$2:$Q$11) - MIN($Q$2:$Q$11)) -> 0.39721155 | U11: =(MAX($R$2:$R$11) - R11) / (MAX($R$2:$R$11) - MIN($R$2:$R$11)) -> 0.35608127 | V11: =0.4*P11 + 0.25*S11 + 0.2*T11 + 0.15*U11 -> 0.28087893 | W11: =AVERAGE(T11,U11) -> 0.37664641
A13: Rankings
A15: Win Percentage Ranks | E15: NRR Ranks | M15: Batting Strength | Q15: Bowling Strength
A17: 1 | B17: =B2 -> GT | C17: =P2 -> 0.71428571 | E17: 1 | F17: =INDEX($B$2:$B$11, MATCH(LARGE($H$2:$H$11,ROW(A1)),$H$2:$H$11,0)) -> GT | H17: =INDEX($S$2:$S$11, MATCH(F17,$B$2:$B$11,0)) -> 1 | M17: 1 | N17: =INDEX($B$2:$B$11, MATCH(LARGE($T$2:$T$11,ROW(A1)),$T$2:$T$11,0)) -> MI | O17: =INDEX($T$2:$T$11, MATCH(N17,$B$2:$B$11,0)) -> 1 | Q17: 1 | R17: =INDEX($B$2:$B$11, MATCH(LARGE($U$2:$U$11,ROW(A1)),$U$2:$U$11,0)) -> GT | S17: =INDEX($U$2:$U$11, MATCH(R17,$B$2:$B$11,0)) -> 1
A18: 2 | B18: =B3 -> CSK | C18: =P3 -> 0.57142857 | E18: 2 | F18: =INDEX($B$2:$B$11, MATCH(LARGE($H$2:$H$11,ROW(A2)),$H$2:$H$11,0)) -> CSK | H18: =INDEX($S$2:$S$11, MATCH(F18,$B$2:$B$11,0)) -> 0.90133797 | M18: 2 | N18: =INDEX($B$2:$B$11, MATCH(LARGE($T$2:$T$11,ROW(A2)),$T$2:$T$11,0)) -> CSK | O18: =INDEX($T$2:$T$11, MATCH(N18,$B$2:$B$11,0)) -> 0.8375001 | Q18: 2 | R18: =INDEX($B$2:$B$11, MATCH(LARGE($U$2:$U$11,ROW(A2)),$U$2:$U$11,0)) -> LSG | S18: =INDEX($U$2:$U$11, MATCH(R18,$B$2:$B$11,0)) -> 0.83423572
A19: 3 | B19: =B4 -> LSG | C19: =P4 -> 0.57142857 | E19: 3 | F19: =INDEX($B$2:$B$11, MATCH(LARGE($H$2:$H$11,ROW(A3)),$H$2:$H$11,0)) -> LSG | H19: =INDEX($S$2:$S$11, MATCH(F19,$B$2:$B$11,0)) -> 0.67541728 | M19: 3 | N19: =INDEX($B$2:$B$11, MATCH(LARGE($T$2:$T$11,ROW(A3)),$T$2:$T$11,0)) -> PBKS | O19: =INDEX($T$2:$T$11, MATCH(N19,$B$2:$B$11,0)) -> 0.73688936 | Q19: 3 | R19: =INDEX($B$2:$B$11, MATCH(LARGE($U$2:$U$11,ROW(A3)),$U$2:$U$11,0)) -> CSK | S19: =INDEX($U$2:$U$11, MATCH(R19,$B$2:$B$11,0)) -> 0.74033124
A20: 4 | B20: =B5 -> MI | C20: =P5 -> 0.57142857 | E20: 4 | F20: =INDEX($B$2:$B$11, MATCH(LARGE($H$2:$H$11,ROW(A4)),$H$2:$H$11,0)) -> RR | H20: =INDEX($S$2:$S$11, MATCH(F20,$B$2:$B$11,0)) -> 0.59093892 | M20: 4 | N20: =INDEX($B$2:$B$11, MATCH(LARGE($T$2:$T$11,ROW(A4)),$T$2:$T$11,0)) -> GT | O20: =INDEX($T$2:$T$11, MATCH(N20,$B$2:$B$11,0)) -> 0.73213478 | Q20: 4 | R20: =INDEX($B$2:$B$11, MATCH(LARGE($U$2:$U$11,ROW(A4)),$U$2:$U$11,0)) -> DC | S20: =INDEX($U$2:$U$11, MATCH(R20,$B$2:$B$11,0)) -> 0.70309482
A21: 5 | B21: =B6 -> RR | C21: =P6 -> 0.5 | E21: 5 | F21: =INDEX($B$2:$B$11, MATCH(LARGE($H$2:$H$11,ROW(A5)),$H$2:$H$11,0)) -> RCB | H21: =INDEX($S$2:$S$11, MATCH(F21,$B$2:$B$11,0)) -> 0.58706649 | M21: 5 | N21: =INDEX($B$2:$B$11, MATCH(LARGE($T$2:$T$11,ROW(A5)),$T$2:$T$11,0)) -> RCB | O21: =INDEX($T$2:$T$11, MATCH(N21,$B$2:$B$11,0)) -> 0.70040781 | Q21: 5 | R21: =INDEX($B$2:$B$11, MATCH(LARGE($U$2:$U$11,ROW(A5)),$U$2:$U$11,0)) -> RR | S21: =INDEX($U$2:$U$11, MATCH(R21,$B$2:$B$11,0)) -> 0.68135114
A22: 6 | B22: =B7 -> RCB | C22: =P7 -> 0.5 | E22: 6 | F22: =INDEX($B$2:$B$11, MATCH(LARGE($H$2:$H$11,ROW(A6)),$H$2:$H$11,0)) -> MI | H22: =INDEX($S$2:$S$11, MATCH(F22,$B$2:$B$11,0)) -> 0.47655051 | M22: 6 | N22: =INDEX($B$2:$B$11, MATCH(LARGE($T$2:$T$11,ROW(A6)),$T$2:$T$11,0)) -> KKR | O22: =INDEX($T$2:$T$11, MATCH(N22,$B$2:$B$11,0)) -> 0.63759553 | Q22: 6 | R22: =INDEX($B$2:$B$11, MATCH(LARGE($U$2:$U$11,ROW(A6)),$U$2:$U$11,0)) -> RCB | S22: =INDEX($U$2:$U$11, MATCH(R22,$B$2:$B$11,0)) -> 0.52639024
A23: 7 | B23: =B8 -> KKR | C23: =P8 -> 0.42857143 | E23: 7 | F23: =INDEX($B$2:$B$11, MATCH(LARGE($H$2:$H$11,ROW(A7)),$H$2:$H$11,0)) -> KKR | H23: =INDEX($S$2:$S$11, MATCH(F23,$B$2:$B$11,0)) -> 0.3569941 | M23: 7 | N23: =INDEX($B$2:$B$11, MATCH(LARGE($T$2:$T$11,ROW(A7)),$T$2:$T$11,0)) -> RR | O23: =INDEX($T$2:$T$11, MATCH(N23,$B$2:$B$11,0)) -> 0.58466809 | Q23: 7 | R23: =INDEX($B$2:$B$11, MATCH(LARGE($U$2:$U$11,ROW(A7)),$U$2:$U$11,0)) -> SRH | S23: =INDEX($U$2:$U$11, MATCH(R23,$B$2:$B$11,0)) -> 0.35608127
A24: 8 | B24: =B9 -> PBKS | C24: =P9 -> 0.42857143 | E24: 8 | F24: =INDEX($B$2:$B$11, MATCH(LARGE($H$2:$H$11,ROW(A8)),$H$2:$H$11,0)) -> PBKS | H24: =INDEX($S$2:$S$11, MATCH(F24,$B$2:$B$11,0)) -> 0.31279846 | M24: 8 | N24: =INDEX($B$2:$B$11, MATCH(LARGE($T$2:$T$11,ROW(A8)),$T$2:$T$11,0)) -> LSG | O24: =INDEX($T$2:$T$11, MATCH(N24,$B$2:$B$11,0)) -> 0.54799315 | Q24: 8 | R24: =INDEX($B$2:$B$11, MATCH(LARGE($U$2:$U$11,ROW(A8)),$U$2:$U$11,0)) -> KKR | S24: =INDEX($U$2:$U$11, MATCH(R24,$B$2:$B$11,0)) -> 0.32105879
A25: 9 | B25: =B10 -> DC | C25: =P10 -> 0.35714286 | E25: 9 | F25: =INDEX($B$2:$B$11, MATCH(LARGE($H$2:$H$11,ROW(A9)),$H$2:$H$11,0)) -> SRH | H25: =INDEX($S$2:$S$11, MATCH(F25,$B$2:$B$11,0)) -> 0.13495484 | M25: 9 | N25: =INDEX($B$2:$B$11, MATCH(LARGE($T$2:$T$11,ROW(A9)),$T$2:$T$11,0)) -> SRH | O25: =INDEX($T$2:$T$11, MATCH(N25,$B$2:$B$11,0)) -> 0.39721155 | Q25: 9 | R25: =INDEX($B$2:$B$11, MATCH(LARGE($U$2:$U$11,ROW(A9)),$U$2:$U$11,0)) -> PBKS | S25: =INDEX($U$2:$U$11, MATCH(R25,$B$2:$B$11,0)) -> 0.13716383
A26: 10 | B26: =B11 -> SRH | C26: =P11 -> 0.28571429 | E26: 10 | F26: =INDEX($B$2:$B$11, MATCH(LARGE($H$2:$H$11,ROW(A10)),$H$2:$H$11,0)) -> DC | H26: =INDEX($S$2:$S$11, MATCH(F26,$B$2:$B$11,0)) -> 0 | M26: 10 | N26: =INDEX($B$2:$B$11, MATCH(LARGE($T$2:$T$11,ROW(A10)),$T$2:$T$11,0)) -> DC | O26: =INDEX($T$2:$T$11, MATCH(N26,$B$2:$B$11,0)) -> 0 | Q26: 10 | R26: =INDEX($B$2:$B$11, MATCH(LARGE($U$2:$U$11,ROW(A10)),$U$2:$U$11,0)) -> MI | S26: =INDEX($U$2:$U$11, MATCH(R26,$B$2:$B$11,0)) -> 0
C30: Season Dominance Index | M30: Balanced Performer Index
C32: 1 | D32: =INDEX($B$2:$B$11, MATCH(LARGE($V$2:$V$11,ROW(A1)),$V$2:$V$11,0)) -> GT | E32: =INDEX($V$2:$V$11, MATCH(D32,$B$2:$B$11,0)) -> 0.83214124 | M32: 1 | N32: =INDEX($B$2:$B$11, MATCH(LARGE($W$2:$W$11,ROW(A1)),$W$2:$W$11,0)) -> GT | O32: =INDEX($W$2:$W$11, MATCH(N32,$B$2:$B$11,0)) -> 0.86606739
C33: 2 | D33: =INDEX($B$2:$B$11, MATCH(LARGE($V$2:$V$11,ROW(A2)),$V$2:$V$11,0)) -> CSK | E33: =INDEX($V$2:$V$11, MATCH(D33,$B$2:$B$11,0)) -> 0.73245563 | M33: 2 | N33: =INDEX($B$2:$B$11, MATCH(LARGE($W$2:$W$11,ROW(A2)),$W$2:$W$11,0)) -> CSK | O33: =INDEX($W$2:$W$11, MATCH(N33,$B$2:$B$11,0)) -> 0.78891567
C34: 3 | D34: =INDEX($B$2:$B$11, MATCH(LARGE($V$2:$V$11,ROW(A3)),$V$2:$V$11,0)) -> LSG | E34: =INDEX($V$2:$V$11, MATCH(D34,$B$2:$B$11,0)) -> 0.63215974 | M34: 3 | N34: =INDEX($B$2:$B$11, MATCH(LARGE($W$2:$W$11,ROW(A3)),$W$2:$W$11,0)) -> LSG | O34: =INDEX($W$2:$W$11, MATCH(N34,$B$2:$B$11,0)) -> 0.69111443
C35: 4 | D35: =INDEX($B$2:$B$11, MATCH(LARGE($V$2:$V$11,ROW(A4)),$V$2:$V$11,0)) -> RR | E35: =INDEX($V$2:$V$11, MATCH(D35,$B$2:$B$11,0)) -> 0.56687102 | M35: 4 | N35: =INDEX($B$2:$B$11, MATCH(LARGE($W$2:$W$11,ROW(A4)),$W$2:$W$11,0)) -> RR | O35: =INDEX($W$2:$W$11, MATCH(N35,$B$2:$B$11,0)) -> 0.63300961
C36: 5 | D36: =INDEX($B$2:$B$11, MATCH(LARGE($V$2:$V$11,ROW(A5)),$V$2:$V$11,0)) -> RCB | E36: =INDEX($V$2:$V$11, MATCH(D36,$B$2:$B$11,0)) -> 0.56580672 | M36: 5 | N36: =INDEX($B$2:$B$11, MATCH(LARGE($W$2:$W$11,ROW(A5)),$W$2:$W$11,0)) -> RCB | O36: =INDEX($W$2:$W$11, MATCH(N36,$B$2:$B$11,0)) -> 0.61339903
C37: 6 | D37: =INDEX($B$2:$B$11, MATCH(LARGE($V$2:$V$11,ROW(A6)),$V$2:$V$11,0)) -> MI | E37: =INDEX($V$2:$V$11, MATCH(D37,$B$2:$B$11,0)) -> 0.54770906 | M37: 6 | N37: =INDEX($B$2:$B$11, MATCH(LARGE($W$2:$W$11,ROW(A6)),$W$2:$W$11,0)) -> MI | O37: =INDEX($W$2:$W$11, MATCH(N37,$B$2:$B$11,0)) -> 0.5
C38: 7 | D38: =INDEX($B$2:$B$11, MATCH(LARGE($V$2:$V$11,ROW(A7)),$V$2:$V$11,0)) -> KKR | E38: =INDEX($V$2:$V$11, MATCH(D38,$B$2:$B$11,0)) -> 0.43635502 | M38: 7 | N38: =INDEX($B$2:$B$11, MATCH(LARGE($W$2:$W$11,ROW(A7)),$W$2:$W$11,0)) -> KKR | O38: =INDEX($W$2:$W$11, MATCH(N38,$B$2:$B$11,0)) -> 0.47932716
C39: 8 | D39: =INDEX($B$2:$B$11, MATCH(LARGE($V$2:$V$11,ROW(A8)),$V$2:$V$11,0)) -> PBKS | E39: =INDEX($V$2:$V$11, MATCH(D39,$B$2:$B$11,0)) -> 0.41758063 | M39: 8 | N39: =INDEX($B$2:$B$11, MATCH(LARGE($W$2:$W$11,ROW(A8)),$W$2:$W$11,0)) -> PBKS | O39: =INDEX($W$2:$W$11, MATCH(N39,$B$2:$B$11,0)) -> 0.43702659
C40: 9 | D40: =INDEX($B$2:$B$11, MATCH(LARGE($V$2:$V$11,ROW(A9)),$V$2:$V$11,0)) -> SRH | E40: =INDEX($V$2:$V$11, MATCH(D40,$B$2:$B$11,0)) -> 0.28087893 | M40: 9 | N40: =INDEX($B$2:$B$11, MATCH(LARGE($W$2:$W$11,ROW(A9)),$W$2:$W$11,0)) -> SRH | O40: =INDEX($W$2:$W$11, MATCH(N40,$B$2:$B$11,0)) -> 0.37664641
C41: 10 | D41: =INDEX($B$2:$B$11, MATCH(LARGE($V$2:$V$11,ROW(A10)),$V$2:$V$11,0)) -> DC | E41: =INDEX($V$2:$V$11, MATCH(D41,$B$2:$B$11,0)) -> 0.24832137 | M41: 10 | N41: =INDEX($B$2:$B$11, MATCH(LARGE($W$2:$W$11,ROW(A10)),$W$2:$W$11,0)) -> DC | O41: =INDEX($W$2:$W$11, MATCH(N41,$B$2:$B$11,0)) -> 0.35154741

Sheet 2024 Data
A1: Rank | B1: Team Name | C1: Matches Played | D1: Wins | E1: Losses | F1: No Result | G1: Net Run Rate (NRR) | H1: Net Run Rate (NRR) | J1: Total Runs Scored | K1: overs faced | L1: Total Runs Conceded | M1: Total Runs Conceded | N1: Overs bowled | O1: Points | P1: Win Percntage | Q1: Batting Runs per Over | R1: Bowling Runs per Over | S1: Normalised NRR | T1: Batting Strength | U1: Bowling Strength | V1: SDI | W1: Balanced Performance
A2: 1 | B2: KKR | C2: 14 | D2: 9 | E2: 3 | F2: 2 | G2: 1.428 | H2: =J2/K2 - M2/N2 -> 1.423118 | I2: 2389/225.0 | J2: 2389 | K2: 225 | L2: 225 | M2: 2135 | N2: 232.2 | O2: =D2*2 + F2*1 -> 20 | P2: =D2/C2 -> 0.64285714 | Q2: =J2/K2 -> 10.617778 | R2: =M2/N2 -> 9.1946598 | S2: =(H2-MIN($H$2:$H$11))/(MAX($H$2:$H$11)-MIN($H$2:$H$11)) -> 1 | T2: =(Q2 - MIN($Q$2:$Q$11)) / (MAX($Q$2:$Q$11) - MIN($Q$2:$Q$11)) -> 1 | U2: =(MAX($R$2:$R$11) - R2) / (MAX($R$2:$R$11) - MIN($R$2:$R$11)) -> 0.70781197 | V2: =0.4*P2 + 0.25*S2 + 0.2*T2 + 0.15*U2 -> 0.81331465 | W2: =AVERAGE(T2,U2) -> 0.85390599
A3: 2 | B3: SRH | C3: 14 | D3: 8 | E3: 5 | F3: 1 | G3: 0.414 | H3: =J3/K3 - M3/N3 -> 0.40609831 | I3: 2605/247.0 | J3: 2605 | K3: 247 | L3: 2599/256.3 | M3: 2599 | N3: 256.3 | O3: =D3*2 + F3*1 -> 17 | P3: =D3/C3 -> 0.57142857 | Q3: =J3/K3 -> 10.546559 | R3: =M3/N3 -> 10.14046 | S3: =(H3-MIN($H$2:$H$11))/(MAX($H$2:$H$11)-MIN($H$2:$H$11)) -> 0.59117534 | T3: =(Q3 - MIN($Q$2:$Q$11)) / (MAX($Q$2:$Q$11) - MIN($Q$2:$Q$11)) -> 0.96531898 | U3: =(MAX($R$2:$R$11) - R3) / (MAX($R$2:$R$11) - MIN($R$2:$R$11)) -> 0 | V3: =0.4*P3 + 0.25*S3 + 0.2*T3 + 0.15*U3 -> 0.56942906 | W3: =AVERAGE(T3,U3) -> 0.48265949
A4: 3 | B4: RR | C4: 14 | D4: 8 | E4: 5 | F4: 1 | G4: 0.273 | H4: =J4/K4 - M4/N4 -> 0.27340006 | I4: 2334/252.1 | J4: 2334 | K4: 252.1 | L4: 2310/257.1 | M4: 2310 | N4: 257.1 | O4: =D4*2 + F4*1 -> 17 | P4: =D4/C4 -> 0.57142857 | Q4: =J4/K4 -> 9.2582309 | R4: =M4/N4 -> 8.9848308 | S4: =(H4-MIN($H$2:$H$11))/(MAX($H$2:$H$11)-MIN($H$2:$H$11)) -> 0.5378329 | T4: =(Q4 - MIN($Q$2:$Q$11)) / (MAX($Q$2:$Q$11) - MIN($Q$2:$Q$11)) -> 0.33795158 | U4: =(MAX($R$2:$R$11) - R4) / (MAX($R$2:$R$11) - MIN($R$2:$R$11)) -> 0.86484238 | V4: =0.4*P4 + 0.25*S4 + 0.2*T4 + 0.15*U4 -> 0.56034633 | W4: =AVERAGE(T4,U4) -> 0.60139698
A5: 4 | B5: RCB | C5: 14 | D5: 7 | E5: 7 | F5: 0 | G5: 0.459 | H5: =J5/K5 - M5/N5 -> 0.45641639 | I5: 2758/269.0 | J5: 2758 | K5: 269 | L5: 2646/270.1 | M5: 2646 | N5: 270.1 | O5: =D5*2 + F5*1 -> 14 | P5: =D5/C5 -> 0.5 | Q5: =J5/K5 -> 10.252788 | R5: =M5/N5 -> 9.7963717 | S5: =(H5-MIN($H$2:$H$11))/(MAX($H$2:$H$11)-MIN($H$2:$H$11)) -> 0.61140236 | T5: =(Q5 - MIN($Q$2:$Q$11)) / (MAX($Q$2:$Q$11) - MIN($Q$2:$Q$11)) -> 0.8222637 | U5: =(MAX($R$2:$R$11) - R5) / (MAX($R$2:$R$11) - MIN($R$2:$R$11)) -> 0.2575068 | V5: =0.4*P5 + 0.25*S5 + 0.2*T5 + 0.15*U5 -> 0.55592935 | W5: =AVERAGE(T5,U5) -> 0.53988525
A6: 5 | B6: CSK | C6: 14 | D6: 7 | E6: 7 | F6: 0 | G6: 0.392 | H6: =J6/K6 - M6/N6 -> 0.39402178 | I6: 2524/274.4 | J6: 2524 | K6: 274.4 | L6: 2415/274.3 | M6: 2415 | N6: 274.3 | O6: =D6*2 + F6*1 -> 14 | P6: =D6/C6 -> 0.5 | Q6: =J6/K6 -> 9.1982507 | R6: =M6/N6 -> 8.8042289 | S6: =(H6-MIN($H$2:$H$11))/(MAX($H$2:$H$11)-MIN($H$2:$H$11)) -> 0.58632078 | T6: =(Q6 - MIN($Q$2:$Q$11)) / (MAX($Q$2:$Q$11) - MIN($Q$2:$Q$11)) -> 0.3087435 | U6: =(MAX($R$2:$R$11) - R6) / (MAX($R$2:$R$11) - MIN($R$2:$R$11)) -> 1 | V6: =0.4*P6 + 0.25*S6 + 0.2*T6 + 0.15*U6 -> 0.5583289 | W6: =AVERAGE(T6,U6) -> 0.65437175
A7: 6 | B7: DC | C7: 14 | D7: 7 | E7: 7 | F7: 0 | G7: -0.377 | H7: =J7/K7 - M7/N7 -> -0.38870423 | I7: 2573/267.0 | J7: 2573 | K7: 267 | L7: 2762/275.5 | M7: 2762 | N7: 275.5 | O7: =D7*2 + F7*1 -> 14 | P7: =D7/C7 -> 0.5 | Q7: =J7/K7 -> 9.6367041 | R7: =M7/N7 -> 10.025408 | S7: =(H7-MIN($H$2:$H$11))/(MAX($H$2:$H$11)-MIN($H$2:$H$11)) -> 0.27167821 | T7: =(Q7 - MIN($Q$2:$Q$11)) / (MAX($Q$2:$Q$11) - MIN($Q$2:$Q$11)) -> 0.52225388 | U7: =(MAX($R$2:$R$11) - R7) / (MAX($R$2:$R$11) - MIN($R$2:$R$11)) -> 0.086101887 | V7: =0.4*P7 + 0.25*S7 + 0.2*T7 + 0.15*U7 -> 0.38528561 | W7: =AVERAGE(T7,U7) -> 0.30417788
A8: 7 | B8: LSG | C8: 14 | D8: 7 | E8: 7 | F8: 0 | G8: -0.667 | H8: =J8/K8 - M8/N8 -> -0.66338454 | I8: 2483/277.5 | J8: 2483 | K8: 277.5 | L8: 2521/262.3 | M8: 2521 | N8: 262.3 | O8: =D8*2 + F8*1 -> 14 | P8: =D8/C8 -> 0.5 | Q8: =J8/K8 -> 8.9477477 | R8: =M8/N8 -> 9.6111323 | S8: =(H8-MIN($H$2:$H$11))/(MAX($H$2:$H$11)-MIN($H$2:$H$11)) -> 0.16126138 | T8: =(Q8 - MIN($Q$2:$Q$11)) / (MAX($Q$2:$Q$11) - MIN($Q$2:$Q$11)) -> 0.18675793 | U8: =(MAX($R$2:$R$11) - R8) / (MAX($R$2:$R$11) - MIN($R$2:$R$11)) -> 0.39613505 | V8: =0.4*P8 + 0.25*S8 + 0.2*T8 + 0.15*U8 -> 0.33708719 | W8: =AVERAGE(T8,U8) -> 0.29144649
A9: 8 | B9: GT | C9: 14 | D9: 5 | E9: 7 | F9: 2 | G9: -1.063 | H9: =J9/K9 - M9/N9 -> -1.0645492 | I9: 2040/238.2 | J9: 2040 | K9: 238.2 | L9: 2101/218.2 | M9: 2101 | N9: 218.2 | O9: =D9*2 + F9*1 -> 12 | P9: =D9/C9 -> 0.35714286 | Q9: =J9/K9 -> 8.5642317 | R9: =M9/N9 -> 9.6287809 | S9: =(H9-MIN($H$2:$H$11))/(MAX($H$2:$H$11)-MIN($H$2:$H$11)) -> 0 | T9: =(Q9 - MIN($Q$2:$Q$11)) / (MAX($Q$2:$Q$11) - MIN($Q$2:$Q$11)) -> 0 | U9: =(MAX($R$2:$R$11) - R9) / (MAX($R$2:$R$11) - MIN($R$2:$R$11)) -> 0.38292727 | V9: =0.4*P9 + 0.25*S9 + 0.2*T9 + 0.15*U9 -> 0.20029623 | W9: =AVERAGE(T9,U9) -> 0.19146364
A10: 9 | B10: PBKS | C10: 14 | D10: 5 | E10: 9 | F10: 0 | G10: -0.353 | H10: =J10/K10 - M10/N10 -> -0.3526861 | I10: 2487/274.3 | J10: 2487 | K10: 274.3 | L10: 2612/277.3 | M10: 2612 | N10: 277.3 | O10: =D10*2 + F10*1 -> 10 | P10: =D10/C10 -> 0.35714286 | Q10: =J10/K10 -> 9.0667153 | R10: =M10/N10 -> 9.4194014 | S10: =(H10-MIN($H$2:$H$11))/(MAX($H$2:$H$11)-MIN($H$2:$H$11)) -> 0.28615689 | T10: =(Q10 - MIN($Q$2:$Q$11)) / (MAX($Q$2:$Q$11) - MIN($Q$2:$Q$11)) -> 0.24469066 | U10: =(MAX($R$2:$R$11) - R10) / (MAX($R$2:$R$11) - MIN($R$2:$R$11)) -> 0.53962136 | V10: =0.4*P10 + 0.25*S10 + 0.2*T10 + 0.15*U10 -> 0.3442777 | W10: =AVERAGE(T10,U10) -> 0.39215601
A11: 10 | B11: MI | C11: 14 | D11: 4 | E11: 10 | F11: 0 | G11: -0.318 | H11: =J11/K11 - M11/N11 -> -0.31321427 | I11: 2568/268.5 | J11: 2568 | K11: 268.5 | L11: 2660/269.3 | M11: 2660 | N11: 269.3 | O11: =D11*2 + F11*1 -> 8 | P11: =D11/C11 -> 0.28571429 | Q11: =J11/K11 -> 9.5642458 | R11: =M11/N11 -> 9.8774601 | S11: =(H11-MIN($H$2:$H$11))/(MAX($H$2:$H$11)-MIN($H$2:$H$11)) -> 0.30202389 | T11: =(Q11 - MIN($Q$2:$Q$11)) / (MAX($Q$2:$Q$11) - MIN($Q$2:$Q$11)) -> 0.48696939 | U11: =(MAX($R$2:$R$11) - R11) / (MAX($R$2:$R$11) - MIN($R$2:$R$11)) -> 0.19682243 | V11: =0.4*P11 + 0.25*S11 + 0.2*T11 + 0.15*U11 -> 0.31670893 | W11: =AVERAGE(T11,U11) -> 0.34189591
A13: Rankings
A15: Win Percentage Ranks | E15: NRR Ranks | M15: Batting Strength | Q15: Bowling Strength
A17: 1 | B17: =B2 -> KKR | C17: =P2 -> 0.64285714 | E17: 1 | F17: =INDEX($B$2:$B$11, MATCH(LARGE($H$2:$H$11,ROW(A1)),$H$2:$H$11,0)) -> KKR | H17: =INDEX($S$2:$S$11, MATCH(F17,$B$2:$B$11,0)) -> 1 | M17: 1 | N17: =INDEX($B$2:$B$11, MATCH(LARGE($T$2:$T$11,ROW(A1)),$T$2:$T$11,0)) -> KKR | O17: =INDEX($T$2:$T$11, MATCH(N17,$B$2:$B$11,0)) -> 1 | Q17: 1 | R17: =INDEX($B$2:$B$11, MATCH(LARGE($U$2:$U$11,ROW(A1)),$U$2:$U$11,0)) -> CSK | S17: =INDEX($U$2:$U$11, MATCH(R17,$B$2:$B$11,0)) -> 1
A18: 2 | B18: =B3 -> SRH | C18: =P3 -> 0.57142857 | E18: 2 | F18: =INDEX($B$2:$B$11, MATCH(LARGE($H$2:$H$11,ROW(A2)),$H$2:$H$11,0)) -> RCB | H18: =INDEX($S$2:$S$11, MATCH(F18,$B$2:$B$11,0)) -> 0.61140236 | M18: 2 | N18: =INDEX($B$2:$B$11, MATCH(LARGE($T$2:$T$11,ROW(A2)),$T$2:$T$11,0)) -> SRH | O18: =INDEX($T$2:$T$11, MATCH(N18,$B$2:$B$11,0)) -> 0.96531898 | Q18: 2 | R18: =INDEX($B$2:$B$11, MATCH(LARGE($U$2:$U$11,ROW(A2)),$U$2:$U$11,0)) -> RR | S18: =INDEX($U$2:$U$11, MATCH(R18,$B$2:$B$11,0)) -> 0.86484238
A19: 3 | B19: =B4 -> RR | C19: =P4 -> 0.57142857 | E19: 3 | F19: =INDEX($B$2:$B$11, MATCH(LARGE($H$2:$H$11,ROW(A3)),$H$2:$H$11,0)) -> SRH | H19: =INDEX($S$2:$S$11, MATCH(F19,$B$2:$B$11,0)) -> 0.59117534 | M19: 3 | N19: =INDEX($B$2:$B$11, MATCH(LARGE($T$2:$T$11,ROW(A3)),$T$2:$T$11,0)) -> RCB | O19: =INDEX($T$2:$T$11, MATCH(N19,$B$2:$B$11,0)) -> 0.8222637 | Q19: 3 | R19: =INDEX($B$2:$B$11, MATCH(LARGE($U$2:$U$11,ROW(A3)),$U$2:$U$11,0)) -> KKR | S19: =INDEX($U$2:$U$11, MATCH(R19,$B$2:$B$11,0)) -> 0.70781197
A20: 4 | B20: =B5 -> RCB | C20: =P5 -> 0.5 | E20: 4 | F20: =INDEX($B$2:$B$11, MATCH(LARGE($H$2:$H$11,ROW(A4)),$H$2:$H$11,0)) -> CSK | H20: =INDEX($S$2:$S$11, MATCH(F20,$B$2:$B$11,0)) -> 0.58632078 | M20: 4 | N20: =INDEX($B$2:$B$11, MATCH(LARGE($T$2:$T$11,ROW(A4)),$T$2:$T$11,0)) -> DC | O20: =INDEX($T$2:$T$11, MATCH(N20,$B$2:$B$11,0)) -> 0.52225388 | Q20: 4 | R20: =INDEX($B$2:$B$11, MATCH(LARGE($U$2:$U$11,ROW(A4)),$U$2:$U$11,0)) -> PBKS | S20: =INDEX($U$2:$U$11, MATCH(R20,$B$2:$B$11,0)) -> 0.53962136
A21: 5 | B21: =B6 -> CSK | C21: =P6 -> 0.5 | E21: 5 | F21: =INDEX($B$2:$B$11, MATCH(LARGE($H$2:$H$11,ROW(A5)),$H$2:$H$11,0)) -> RR | H21: =INDEX($S$2:$S$11, MATCH(F21,$B$2:$B$11,0)) -> 0.5378329 | M21: 5 | N21: =INDEX($B$2:$B$11, MATCH(LARGE($T$2:$T$11,ROW(A5)),$T$2:$T$11,0)) -> MI | O21: =INDEX($T$2:$T$11, MATCH(N21,$B$2:$B$11,0)) -> 0.48696939 | Q21: 5 | R21: =INDEX($B$2:$B$11, MATCH(LARGE($U$2:$U$11,ROW(A5)),$U$2:$U$11,0)) -> LSG | S21: =INDEX($U$2:$U$11, MATCH(R21,$B$2:$B$11,0)) -> 0.39613505
A22: 6 | B22: =B7 -> DC | C22: =P7 -> 0.5 | E22: 6 | F22: =INDEX($B$2:$B$11, MATCH(LARGE($H$2:$H$11,ROW(A6)),$H$2:$H$11,0)) -> MI | H22: =INDEX($S$2:$S$11, MATCH(F22,$B$2:$B$11,0)) -> 0.30202389 | M22: 6 | N22: =INDEX($B$2:$B$11, MATCH(LARGE($T$2:$T$11,ROW(A6)),$T$2:$T$11,0)) -> RR | O22: =INDEX($T$2:$T$11, MATCH(N22,$B$2:$B$11,0)) -> 0.33795158 | Q22: 6 | R22: =INDEX($B$2:$B$11, MATCH(LARGE($U$2:$U$11,ROW(A6)),$U$2:$U$11,0)) -> GT | S22: =INDEX($U$2:$U$11, MATCH(R22,$B$2:$B$11,0)) -> 0.38292727
A23: 7 | B23: =B8 -> LSG | C23: =P8 -> 0.5 | E23: 7 | F23: =INDEX($B$2:$B$11, MATCH(LARGE($H$2:$H$11,ROW(A7)),$H$2:$H$11,0)) -> PBKS | H23: =INDEX($S$2:$S$11, MATCH(F23,$B$2:$B$11,0)) -> 0.28615689 | M23: 7 | N23: =INDEX($B$2:$B$11, MATCH(LARGE($T$2:$T$11,ROW(A7)),$T$2:$T$11,0)) -> CSK | O23: =INDEX($T$2:$T$11, MATCH(N23,$B$2:$B$11,0)) -> 0.3087435 | Q23: 7 | R23: =INDEX($B$2:$B$11, MATCH(LARGE($U$2:$U$11,ROW(A7)),$U$2:$U$11,0)) -> RCB | S23: =INDEX($U$2:$U$11, MATCH(R23,$B$2:$B$11,0)) -> 0.2575068
A24: 8 | B24: =B9 -> GT | C24: =P9 -> 0.35714286 | E24: 8 | F24: =INDEX($B$2:$B$11, MATCH(LARGE($H$2:$H$11,ROW(A8)),$H$2:$H$11,0)) -> DC | H24: =INDEX($S$2:$S$11, MATCH(F24,$B$2:$B$11,0)) -> 0.27167821 | M24: 8 | N24: =INDEX($B$2:$B$11, MATCH(LARGE($T$2:$T$11,ROW(A8)),$T$2:$T$11,0)) -> PBKS | O24: =INDEX($T$2:$T$11, MATCH(N24,$B$2:$B$11,0)) -> 0.24469066 | Q24: 8 | R24: =INDEX($B$2:$B$11, MATCH(LARGE($U$2:$U$11,ROW(A8)),$U$2:$U$11,0)) -> MI | S24: =INDEX($U$2:$U$11, MATCH(R24,$B$2:$B$11,0)) -> 0.19682243
A25: 9 | B25: =B10 -> PBKS | C25: =P10 -> 0.35714286 | E25: 9 | F25: =INDEX($B$2:$B$11, MATCH(LARGE($H$2:$H$11,ROW(A9)),$H$2:$H$11,0)) -> LSG | H25: =INDEX($S$2:$S$11, MATCH(F25,$B$2:$B$11,0)) -> 0.16126138 | M25: 9 | N25: =INDEX($B$2:$B$11, MATCH(LARGE($T$2:$T$11,ROW(A9)),$T$2:$T$11,0)) -> LSG | O25: =INDEX($T$2:$T$11, MATCH(N25,$B$2:$B$11,0)) -> 0.18675793 | Q25: 9 | R25: =INDEX($B$2:$B$11, MATCH(LARGE($U$2:$U$11,ROW(A9)),$U$2:$U$11,0)) -> DC | S25: =INDEX($U$2:$U$11, MATCH(R25,$B$2:$B$11,0)) -> 0.086101887
A26: 10 | B26: =B11 -> MI | C26: =P11 -> 0.28571429 | E26: 10 | F26: =INDEX($B$2:$B$11, MATCH(LARGE($H$2:$H$11,ROW(A10)),$H$2:$H$11,0)) -> GT | H26: =INDEX($S$2:$S$11, MATCH(F26,$B$2:$B$11,0)) -> 0 | M26: 10 | N26: =INDEX($B$2:$B$11, MATCH(LARGE($T$2:$T$11,ROW(A10)),$T$2:$T$11,0)) -> GT | O26: =INDEX($T$2:$T$11, MATCH(N26,$B$2:$B$11,0)) -> 0 | Q26: 10 | R26: =INDEX($B$2:$B$11, MATCH(LARGE($U$2:$U$11,ROW(A10)),$U$2:$U$11,0)) -> SRH | S26: =INDEX($U$2:$U$11, MATCH(R26,$B$2:$B$11,0)) -> 0
C30: Season Dominance Index | F30: Balanced Performer Index
C32: 1 | D32: =INDEX($B$2:$B$11, MATCH(LARGE($V$2:$V$11,ROW(A1)),$V$2:$V$11,0)) -> KKR | E32: =INDEX($V$2:$V$11, MATCH(D32,$B$2:$B$11,0)) -> 0.81331465 | F32: 1 | G32: =INDEX($B$2:$B$11, MATCH(LARGE($W$2:$W$11,ROW(A1)),$W$2:$W$11,0)) -> KKR | H32: =INDEX($W$2:$W$11, MATCH(G32,$B$2:$B$11,0)) -> 0.85390599
C33: 2 | D33: =INDEX($B$2:$B$11, MATCH(LARGE($V$2:$V$11,ROW(A2)),$V$2:$V$11,0)) -> SRH | E33: =INDEX($V$2:$V$11, MATCH(D33,$B$2:$B$11,0)) -> 0.56942906 | F33: 2 | G33: =INDEX($B$2:$B$11, MATCH(LARGE($W$2:$W$11,ROW(A2)),$W$2:$W$11,0)) -> CSK | H33: =INDEX($W$2:$W$11, MATCH(G33,$B$2:$B$11,0)) -> 0.65437175
C34: 3 | D34: =INDEX($B$2:$B$11, MATCH(LARGE($V$2:$V$11,ROW(A3)),$V$2:$V$11,0)) -> RR | E34: =INDEX($V$2:$V$11, MATCH(D34,$B$2:$B$11,0)) -> 0.56034633 | F34: 3 | G34: =INDEX($B$2:$B$11, MATCH(LARGE($W$2:$W$11,ROW(A3)),$W$2:$W$11,0)) -> RR | H34: =INDEX($W$2:$W$11, MATCH(G34,$B$2:$B$11,0)) -> 0.60139698
C35: 4 | D35: =INDEX($B$2:$B$11, MATCH(LARGE($V$2:$V$11,ROW(A4)),$V$2:$V$11,0)) -> CSK | E35: =INDEX($V$2:$V$11, MATCH(D35,$B$2:$B$11,0)) -> 0.5583289 | F35: 4 | G35: =INDEX($B$2:$B$11, MATCH(LARGE($W$2:$W$11,ROW(A4)),$W$2:$W$11,0)) -> RCB | H35: =INDEX($W$2:$W$11, MATCH(G35,$B$2:$B$11,0)) -> 0.53988525
C36: 5 | D36: =INDEX($B$2:$B$11, MATCH(LARGE($V$2:$V$11,ROW(A5)),$V$2:$V$11,0)) -> RCB | E36: =INDEX($V$2:$V$11, MATCH(D36,$B$2:$B$11,0)) -> 0.55592935 | F36: 5 | G36: =INDEX($B$2:$B$11, MATCH(LARGE($W$2:$W$11,ROW(A5)),$W$2:$W$11,0)) -> SRH | H36: =INDEX($W$2:$W$11, MATCH(G36,$B$2:$B$11,0)) -> 0.48265949
C37: 6 | D37: =INDEX($B$2:$B$11, MATCH(LARGE($V$2:$V$11,ROW(A6)),$V$2:$V$11,0)) -> DC | E37: =INDEX($V$2:$V$11, MATCH(D37,$B$2:$B$11,0)) -> 0.38528561 | F37: 6 | G37: =INDEX($B$2:$B$11, MATCH(LARGE($W$2:$W$11,ROW(A6)),$W$2:$W$11,0)) -> PBKS | H37: =INDEX($W$2:$W$11, MATCH(G37,$B$2:$B$11,0)) -> 0.39215601
C38: 7 | D38: =INDEX($B$2:$B$11, MATCH(LARGE($V$2:$V$11,ROW(A7)),$V$2:$V$11,0)) -> PBKS | E38: =INDEX($V$2:$V$11, MATCH(D38,$B$2:$B$11,0)) -> 0.3442777 | F38: 7 | G38: =INDEX($B$2:$B$11, MATCH(LARGE($W$2:$W$11,ROW(A7)),$W$2:$W$11,0)) -> MI | H38: =INDEX($W$2:$W$11, MATCH(G38,$B$2:$B$11,0)) -> 0.34189591
C39: 8 | D39: =INDEX($B$2:$B$11, MATCH(LARGE($V$2:$V$11,ROW(A8)),$V$2:$V$11,0)) -> LSG | E39: =INDEX($V$2:$V$11, MATCH(D39,$B$2:$B$11,0)) -> 0.33708719 | F39: 8 | G39: =INDEX($B$2:$B$11, MATCH(LARGE($W$2:$W$11,ROW(A8)),$W$2:$W$11,0)) -> DC | H39: =INDEX($W$2:$W$11, MATCH(G39,$B$2:$B$11,0)) -> 0.30417788
C40: 9 | D40: =INDEX($B$2:$B$11, MATCH(LARGE($V$2:$V$11,ROW(A9)),$V$2:$V$11,0)) -> MI | E40: =INDEX($V$2:$V$11, MATCH(D40,$B$2:$B$11,0)) -> 0.31670893 | F40: 9 | G40: =INDEX($B$2:$B$11, MATCH(LARGE($W$2:$W$11,ROW(A9)),$W$2:$W$11,0)) -> LSG | H40: =INDEX($W$2:$W$11, MATCH(G40,$B$2:$B$11,0)) -> 0.29144649
C41: 10 | D41: =INDEX($B$2:$B$11, MATCH(LARGE($V$2:$V$11,ROW(A10)),$V$2:$V$11,0)) -> GT | E41: =INDEX($V$2:$V$11, MATCH(D41,$B$2:$B$11,0)) -> 0.20029623 | F41: 10 | G41: =INDEX($B$2:$B$11, MATCH(LARGE($W$2:$W$11,ROW(A10)),$W$2:$W$11,0)) -> GT | H41: =INDEX($W$2:$W$11, MATCH(G41,$B$2:$B$11,0)) -> 0.19146364

Sheet All season Rankings
A2: 2024 Rankings | K2: 2022 Rankings | U2: 2023 Rankings | AE2: Overall Rankings
A4: Win Percentage Ranks | D4: NRR Ranks | G4: Batting Strength | K4: Win Percentage Ranks | N4: NRR Ranks | Q4: Batting Strength | U4: Win Percentage Ranks | X4: NRR Ranks | AA4: Batting Strength | AE4: Win Percentage Ranks | AH4: NRR Ranks | AK4: Batting Strength
A6: 1 | B6: KKR | C6: 0.64285714 | D6: 1 | E6: KKR | F6: 1 | G6: 1 | H6: KKR | I6: 1 | K6: ='2022 Data'!A17 -> 1 | L6: ='2022 Data'!B17 -> GT | M6: ='2022 Data'!C17 -> 0.71428571 | N6: ='2022 Data'!E17 -> 1 | O6: ='2022 Data'!F17 -> GT | P6: ='2022 Data'!H17 -> 1 | Q6: ='2022 Data'!M17 -> 1 | R6: ='2022 Data'!N17 -> RR | S6: ='2022 Data'!O17 -> 1 | U6: 1 | V6: ='2023 Data'!B17 -> GT | W6: ='2023 Data'!C17 -> 0.71428571 | X6: 1 | Y6: ='2022 Data'!F17 -> GT | Z6: ='2023 Data'!H17 -> 1 | AA6: 1 | AB6: ='2023 Data'!N17 -> MI | AC6: ='2023 Data'!O17 -> 1 | AE6: 1 | AF6: ='Overall Ranks'!B14 -> GT | AG6: ='Overall Ranks'!C14 -> 0.5952381 | AH6: 1 | AI6: ='Overall Ranks'!B29 -> KKR | AJ6: ='Overall Ranks'!C29 -> 0.75802579 | AK6: 1 | AL6: ='Overall Ranks'!B43 -> KKR | AM6: ='Overall Ranks'!C43 -> 0.64456683
A7: 2 | B7: SRH | C7: 0.57142857 | D7: 2 | E7: RCB | F7: 0.61140236 | G7: 2 | H7: SRH | I7: 0.96531898 | K7: ='2022 Data'!A18 -> 2 | L7: SRH | M7: ='2022 Data'!C18 -> 0.64285714 | N7: ='2022 Data'!E18 -> 2 | O7: ='2022 Data'!F18 -> RR | P7: ='2022 Data'!H18 -> 0.98928042 | Q7: ='2022 Data'!M18 -> 2 | R7: ='2022 Data'!N18 -> DC | S7: ='2022 Data'!O18 -> 0.96555866 | U7: 2 | V7: ='2023 Data'!B18 -> CSK | W7: ='2023 Data'!C18 -> 0.57142857 | X7: 2 | Y7: ='2022 Data'!F18 -> RR | Z7: ='2023 Data'!H18 -> 0.90133797 | AA7: 2 | AB7: ='2023 Data'!N18 -> CSK | AC7: ='2023 Data'!O18 -> 0.8375001 | AE7: 2 | AF7: ='Overall Ranks'!B15 -> LSG | AG7: ='Overall Ranks'!C15 -> 0.57142857 | AH7: 2 | AI7: ='Overall Ranks'!B30 -> RR | AJ7: ='Overall Ranks'!C30 -> 0.70601741 | AK7: 2 | AL7: ='Overall Ranks'!B44 -> RR | AM7: ='Overall Ranks'!C44 -> 0.64087322
A8: 3 | B8: RR | C8: 0.57142857 | D8: 3 | E8: SRH | F8: 0.59117534 | G8: 3 | H8: RCB | I8: 0.8222637 | K8: ='2022 Data'!A19 -> 3 | L8: RR | M8: ='2022 Data'!C19 -> 0.64285714 | N8: ='2022 Data'!E19 -> 3 | O8: ='2022 Data'!F19 -> LSG | P8: ='2022 Data'!H19 -> 0.9593931 | Q8: ='2022 Data'!M19 -> 3 | R8: ='2022 Data'!N19 -> PBKS | S8: ='2022 Data'!O19 -> 0.78790089 | U8: 3 | V8: ='2023 Data'!B19 -> LSG | W8: ='2023 Data'!C19 -> 0.57142857 | X8: 3 | Y8: ='2022 Data'!F19 -> LSG | Z8: ='2023 Data'!H19 -> 0.67541728 | AA8: 3 | AB8: ='2023 Data'!N19 -> PBKS | AC8: ='2023 Data'!O19 -> 0.73688936 | AE8: 3 | AF8: ='Overall Ranks'!B16 -> RR | AG8: ='Overall Ranks'!C16 -> 0.57142857 | AH8: 3 | AI8: ='Overall Ranks'!B31 -> GT | AJ8: ='Overall Ranks'!C31 -> 0.66666667 | AK8: 3 | AL8: ='Overall Ranks'!B45 -> PBKS | AM8: ='Overall Ranks'!C45 -> 0.58982697
A9: 4 | B9: RCB | C9: 0.5 | D9: 4 | E9: CSK | F9: 0.58632078 | G9: 4 | H9: DC | I9: 0.52225388 | K9: ='2022 Data'!A20 -> 4 | L9: RCB | M9: ='2022 Data'!C20 -> 0.57142857 | N9: ='2022 Data'!E20 -> 4 | O9: ='2022 Data'!F20 -> DC | P9: ='2022 Data'!H20 -> 0.9262877 | Q9: ='2022 Data'!M20 -> 4 | R9: ='2022 Data'!N20 -> LSG | S9: ='2022 Data'!O20 -> 0.45461146 | U9: 4 | V9: ='2023 Data'!B20 -> MI | W9: ='2023 Data'!C20 -> 0.57142857 | X9: 4 | Y9: ='2022 Data'!F20 -> DC | Z9: ='2023 Data'!H20 -> 0.59093892 | AA9: 4 | AB9: ='2023 Data'!N20 -> GT | AC9: ='2023 Data'!O20 -> 0.73213478 | AE9: 4 | AF9: ='Overall Ranks'!B17 -> RCB | AG9: ='Overall Ranks'!C17 -> 0.52380952 | AH9: 4 | AI9: ='Overall Ranks'!B32 -> RCB | AJ9: ='Overall Ranks'!C32 -> 0.61255757 | AK9: 4 | AL9: ='Overall Ranks'!B46 -> RCB | AM9: ='Overall Ranks'!C46 -> 0.56404188
A10: 5 | B10: CSK | C10: 0.5 | D10: 5 | E10: RR | F10: 0.5378329 | G10: 5 | H10: MI | I10: 0.48696939 | K10: ='2022 Data'!A21 -> 5 | L10: CSK | M10: ='2022 Data'!C21 -> 0.5 | N10: ='2022 Data'!E21 -> 5 | O10: ='2022 Data'!F21 -> KKR | P10: ='2022 Data'!H21 -> 0.91708328 | Q10: ='2022 Data'!M21 -> 5 | R10: ='2022 Data'!N21 -> GT | S10: ='2022 Data'!O21 -> 0.41632766 | U10: 5 | V10: ='2023 Data'!B21 -> RR | W10: ='2023 Data'!C21 -> 0.5 | X10: 5 | Y10: ='2022 Data'!F21 -> KKR | Z10: ='2023 Data'!H21 -> 0.58706649 | AA10: 5 | AB10: ='2023 Data'!N21 -> RCB | AC10: ='2023 Data'!O21 -> 0.70040781 | AE10: 5 | AF10: ='Overall Ranks'!B18 -> KKR | AG10: ='Overall Ranks'!C18 -> 0.5 | AH10: 5 | AI10: ='Overall Ranks'!B33 -> LSG | AJ10: ='Overall Ranks'!C33 -> 0.59869059 | AK10: 5 | AL10: ='Overall Ranks'!B47 -> SRH | AM10: ='Overall Ranks'!C47 -> 0.5617212
A11: 6 | B11: DC | C11: 0.5 | D11: 6 | E11: MI | F11: 0.30202389 | G11: 6 | H11: RR | I11: 0.33795158 | K11: ='2022 Data'!A22 -> 6 | L11: DC | M11: ='2022 Data'!C22 -> 0.5 | N11: ='2022 Data'!E22 -> 6 | O11: ='2022 Data'!F22 -> PBKS | P11: ='2022 Data'!H22 -> 0.87964688 | Q11: ='2022 Data'!M22 -> 6 | R11: ='2022 Data'!N22 -> SRH | S11: ='2022 Data'!O22 -> 0.32263308 | U11: 6 | V11: ='2023 Data'!B22 -> RCB | W11: ='2023 Data'!C22 -> 0.5 | X11: 6 | Y11: ='2022 Data'!F22 -> PBKS | Z11: ='2023 Data'!H22 -> 0.47655051 | AA11: 6 | AB11: ='2023 Data'!N22 -> KKR | AC11: ='2023 Data'!O22 -> 0.63759553 | AE11: 6 | AF11: ='Overall Ranks'!B19 -> DC | AG11: ='Overall Ranks'!C19 -> 0.45238095 | AH11: 6 | AI11: ='Overall Ranks'!B34 -> CSK | AJ11: ='Overall Ranks'!C34 -> 0.5033818 | AK11: 6 | AL11: ='Overall Ranks'!B48 -> DC | AM11: ='Overall Ranks'!C48 -> 0.49593751
A12: 7 | B12: LSG | C12: 0.5 | D12: 7 | E12: PBKS | F12: 0.28615689 | G12: 7 | H12: CSK | I12: 0.3087435 | K12: ='2022 Data'!A23 -> 7 | L12: LSG | M12: ='2022 Data'!C23 -> 0.42857143 | N12: ='2022 Data'!E23 -> 7 | O12: ='2022 Data'!F23 -> RCB | P12: ='2022 Data'!H23 -> 0.63920387 | Q12: ='2022 Data'!M23 -> 7 | R12: ='2022 Data'!N23 -> KKR | S12: ='2022 Data'!O23 -> 0.29610495 | U12: 7 | V12: ='2023 Data'!B23 -> KKR | W12: ='2023 Data'!C23 -> 0.42857143 | X12: 7 | Y12: ='2022 Data'!F23 -> RCB | Z12: ='2023 Data'!H23 -> 0.3569941 | AA12: 7 | AB12: ='2023 Data'!N23 -> RR | AC12: ='2023 Data'!O23 -> 0.58466809 | AE12: 7 | AF12: ='Overall Ranks'!B20 -> CSK | AG12: ='Overall Ranks'!C20 -> 0.45238095 | AH12: 7 | AI12: ='Overall Ranks'!B35 -> PBKS | AJ12: ='Overall Ranks'!C35 -> 0.49286741 | AK12: 7 | AL12: ='Overall Ranks'!B49 -> MI | AM12: ='Overall Ranks'!C49 -> 0.49565646
A13: 8 | B13: GT | C13: 0.35714286 | D13: 8 | E13: DC | F13: 0.27167821 | G13: 8 | H13: PBKS | I13: 0.24469066 | K13: ='2022 Data'!A24 -> 8 | L13: GT | M13: ='2022 Data'!C24 -> 0.42857143 | N13: ='2022 Data'!E24 -> 8 | O13: ='2022 Data'!F24 -> SRH | P13: ='2022 Data'!H24 -> 0.51878093 | Q13: ='2022 Data'!M24 -> 8 | R13: ='2022 Data'!N24 -> RCB | S13: ='2022 Data'!O24 -> 0.16945412 | U13: 8 | V13: ='2023 Data'!B24 -> PBKS | W13: ='2023 Data'!C24 -> 0.42857143 | X13: 8 | Y13: ='2022 Data'!F24 -> SRH | Z13: ='2023 Data'!H24 -> 0.31279846 | AA13: 8 | AB13: ='2023 Data'!N24 -> LSG | AC13: ='2023 Data'!O24 -> 0.54799315 | AE13: 8 | AF13: ='Overall Ranks'!B21 -> PBKS | AG13: ='Overall Ranks'!C21 -> 0.42857143 | AH13: 8 | AI13: ='Overall Ranks'!B36 -> SRH | AJ13: ='Overall Ranks'!C36 -> 0.41497037 | AK13: 8 | AL13: ='Overall Ranks'!B50 -> CSK | AM13: ='Overall Ranks'!C50 -> 0.40859393
A14: 9 | B14: PBKS | C14: 0.35714286 | D14: 9 | E14: LSG | F14: 0.16126138 | G14: 9 | H14: LSG | I14: 0.18675793 | K14: ='2022 Data'!A25 -> 9 | L14: PBKS | M14: ='2022 Data'!C25 -> 0.28571429 | N14: ='2022 Data'!E25 -> 9 | O14: ='2022 Data'!F25 -> CSK | P14: ='2022 Data'!H25 -> 0.022486664 | Q14: ='2022 Data'!M25 -> 9 | R14: ='2022 Data'!N25 -> CSK | S14: ='2022 Data'!O25 -> 0.079538203 | U14: 9 | V14: ='2023 Data'!B25 -> DC | W14: ='2023 Data'!C25 -> 0.35714286 | X14: 9 | Y14: ='2022 Data'!F25 -> CSK | Z14: ='2023 Data'!H25 -> 0.13495484 | AA14: 9 | AB14: ='2023 Data'!N25 -> SRH | AC14: ='2023 Data'!O25 -> 0.39721155 | AE14: 9 | AF14: ='Overall Ranks'!B22 -> SRH | AG14: ='Overall Ranks'!C22 -> 0.42857143 | AH14: 9 | AI14: ='Overall Ranks'!B37 -> DC | AJ14: ='Overall Ranks'!C37 -> 0.39932197 | AK14: 9 | AL14: ='Overall Ranks'!B51 -> LSG | AM14: ='Overall Ranks'!C51 -> 0.39645418
A15: 10 | B15: MI | C15: 0.28571429 | D15: 10 | E15: GT | F15: 0 | G15: 10 | H15: GT | I15: 0 | K15: ='2022 Data'!A26 -> 10 | L15: MI | M15: ='2022 Data'!C26 -> 0.28571429 | N15: ='2022 Data'!E26 -> 10 | O15: ='2022 Data'!F26 -> MI | P15: ='2022 Data'!H26 -> 0 | Q15: ='2022 Data'!M26 -> 10 | R15: ='2022 Data'!N26 -> MI | S15: ='2022 Data'!O26 -> 0 | U15: 10 | V15: ='2023 Data'!B26 -> SRH | W15: ='2023 Data'!C26 -> 0.28571429 | X15: 10 | Y15: ='2022 Data'!F26 -> MI | Z15: ='2023 Data'!H26 -> 0 | AA15: 10 | AB15: ='2023 Data'!N26 -> DC | AC15: ='2023 Data'!O26 -> 0 | AE15: 10 | AF15: ='Overall Ranks'!B23 -> MI | AG15: ='Overall Ranks'!C23 -> 0.38095238 | AH15: 10 | AI15: ='Overall Ranks'!B38 -> MI | AJ15: ='Overall Ranks'!C38 -> 0.2595248 | AK15: 10 | AL15: ='Overall Ranks'!B52 -> GT | AM15: ='Overall Ranks'!C52 -> 0.38282081
A17: Bowling Strength | D17: Season Dominance Index | G17: Balanced Performer Index | K17: Bowling Strength | N17: Season Dominance Index | Q17: Balanced Performer Index | U17: Bowling Strength | X17: Season Dominance Index | AA17: Balanced Performer Index | AE17: Bowling Strength | AH17: Season Dominance Index | AK17: Balanced Performer Index
A19: 1 | B19: CSK | C19: 1 | D19: 1 | E19: KKR | F19: 0.81331465 | G19: 1 | H19: KKR | I19: 0.85390599 | K19: 1 | L19: ='2022 Data'!R17 -> GT | M19: ='2022 Data'!S17 -> 1 | N19: 1 | O19: ='2022 Data'!D32 -> RR | P19: ='2022 Data'!E32 -> 0.80381459 | Q19: 1 | R19: ='2022 Data'!N32 -> RR | S19: ='2022 Data'!O32 -> 0.83117209 | U19: 1 | V19: ='2023 Data'!R17 -> GT | W19: ='2023 Data'!S17 -> 1 | X19: 1 | Y19: ='2023 Data'!D32 -> GT | Z19: ='2023 Data'!E32 -> 0.83214124 | AA19: 1 | AB19: ='2023 Data'!N32 -> GT | AC19: ='2023 Data'!O32 -> 0.86606739 | AE19: 1 | AF19: ='Overall Ranks'!B57 -> GT | AG19: ='Overall Ranks'!C57 -> 0.79430909 | AH19: 1 | AI19: ='Overall Ranks'!B84 -> RR | AJ19: ='Overall Ranks'!C84 -> 0.64367731 | AK19: 1 | AL19: ='Overall Ranks'!B71 -> RR | AM19: ='Overall Ranks'!C71 -> 0.68852623
A20: 2 | B20: RR | C20: 0.86484238 | D20: 2 | E20: SRH | F20: 0.56942906 | G20: 2 | H20: CSK | I20: 0.65437175 | K20: 2 | L20: ='2022 Data'!R18 -> KKR | M20: ='2022 Data'!S18 -> 0.9661538 | N20: 2 | O20: ='2022 Data'!D33 -> GT | P20: ='2022 Data'!E33 -> 0.76897982 | Q20: 2 | R20: ='2022 Data'!N33 -> DC | S20: ='2022 Data'!O33 -> 0.78527293 | U20: 2 | V20: ='2023 Data'!R18 -> LSG | W20: ='2023 Data'!S18 -> 0.83423572 | X20: 2 | Y20: ='2023 Data'!D33 -> CSK | Z20: ='2023 Data'!E33 -> 0.73245563 | AA20: 2 | AB20: ='2023 Data'!N33 -> CSK | AC20: ='2023 Data'!O33 -> 0.78891567 | AE20: 2 | AF20: ='Overall Ranks'!B58 -> RR | AG20: ='Overall Ranks'!C58 -> 0.73617924 | AH20: 2 | AI20: ='Overall Ranks'!B85 -> KKR | AJ20: ='Overall Ranks'!C85 -> 0.61817104 | AK20: 2 | AL20: ='Overall Ranks'!B72 -> KKR | AM20: ='Overall Ranks'!C72 -> 0.65478751
A21: 3 | B21: KKR | C21: 0.70781197 | D21: 3 | E21: RR | F21: 0.56034633 | G21: 3 | H21: RR | I21: 0.60139698 | K21: 3 | L21: ='2022 Data'!R19 -> LSG | M21: ='2022 Data'!S19 -> 0.92938425 | N21: 3 | O21: ='2022 Data'!D34 -> LSG | P21: ='2022 Data'!E34 -> 0.72732106 | Q21: 3 | R21: ='2022 Data'!N34 -> PBKS | S21: ='2022 Data'!O34 -> 0.71752445 | U21: 3 | V21: ='2023 Data'!R19 -> CSK | W21: ='2023 Data'!S19 -> 0.74033124 | X21: 3 | Y21: ='2023 Data'!D34 -> LSG | Z21: ='2023 Data'!E34 -> 0.63215974 | AA21: 3 | AB21: ='2023 Data'!N34 -> LSG | AC21: ='2023 Data'!O34 -> 0.69111443 | AE21: 3 | AF21: ='Overall Ranks'!B59 -> LSG | AG21: ='Overall Ranks'!C59 -> 0.71991834 | AH21: 3 | AI21: ='Overall Ranks'!B86 -> GT | AJ21: ='Overall Ranks'!C86 -> 0.60047243 | AK21: 3 | AL21: ='Overall Ranks'!B73 -> GT | AM21: ='Overall Ranks'!C73 -> 0.58856495
A22: 4 | B22: PBKS | C22: 0.53962136 | D22: 4 | E22: CSK | F22: 0.5583289 | G22: 4 | H22: RCB | I22: 0.53988525 | K22: 4 | L22: ='2022 Data'!R20 -> RCB | M22: ='2022 Data'!S20 -> 0.69907466 | N22: 4 | O22: ='2022 Data'!D35 -> DC | P22: ='2022 Data'!E35 -> 0.71543174 | Q22: 4 | R22: ='2022 Data'!N35 -> GT | S22: ='2022 Data'!O35 -> 0.70816383 | U22: 4 | V22: ='2023 Data'!R20 -> DC | W22: ='2023 Data'!S20 -> 0.70309482 | X22: 4 | Y22: ='2023 Data'!D35 -> RR | Z22: ='2023 Data'!E35 -> 0.56687102 | AA22: 4 | AB22: ='2023 Data'!N35 -> RR | AC22: ='2023 Data'!O35 -> 0.63300961 | AE22: 4 | AF22: ='Overall Ranks'!B60 -> KKR | AG22: ='Overall Ranks'!C60 -> 0.66500819 | AH22: 4 | AI22: ='Overall Ranks'!B87 -> LSG | AJ22: ='Overall Ranks'!C87 -> 0.56552266 | AK22: 4 | AL22: ='Overall Ranks'!B74 -> LSG | AM22: ='Overall Ranks'!C74 -> 0.55818626
A23: 5 | B23: LSG | C23: 0.39613505 | D23: 5 | E23: RCB | F23: 0.55592935 | G23: 5 | H23: SRH | I23: 0.48265949 | K23: 5 | L23: ='2022 Data'!R21 -> RR | M23: ='2022 Data'!S21 -> 0.66234419 | N23: 5 | O23: ='2022 Data'!D36 -> PBKS | P23: ='2022 Data'!E36 -> 0.6745641 | Q23: 5 | R23: ='2022 Data'!N36 -> LSG | S23: ='2022 Data'!O36 -> 0.69199786 | U23: 5 | V23: ='2023 Data'!R21 -> RR | W23: ='2023 Data'!S21 -> 0.68135114 | X23: 5 | Y23: ='2023 Data'!D36 -> RCB | Z23: ='2023 Data'!E36 -> 0.56580672 | AA23: 5 | AB23: ='2023 Data'!N36 -> RCB | AC23: ='2023 Data'!O36 -> 0.61339903 | AE23: 5 | AF23: ='Overall Ranks'!B61 -> CSK | AG23: ='Overall Ranks'!C61 -> 0.58011041 | AH23: 5 | AI23: ='Overall Ranks'!B88 -> RCB | AJ23: ='Overall Ranks'!C88 -> 0.54962016 | AK23: 5 | AL23: ='Overall Ranks'!B75 -> RCB | AM23: ='Overall Ranks'!C75 -> 0.52918289
A24: 6 | B24: GT | C24: 0.38292727 | D24: 6 | E24: DC | F24: 0.38528561 | G24: 6 | H24: PBKS | I24: 0.39215601 | K24: 6 | L24: ='2022 Data'!R22 -> PBKS | M24: ='2022 Data'!S22 -> 0.64714801 | N24: 6 | O24: ='2022 Data'!D37 -> KKR | P24: ='2022 Data'!E37 -> 0.60484345 | Q24: 6 | R24: ='2022 Data'!N37 -> KKR | S24: ='2022 Data'!O37 -> 0.63112938 | U24: 6 | V24: ='2023 Data'!R22 -> RCB | W24: ='2023 Data'!S22 -> 0.52639024 | X24: 6 | Y24: ='2023 Data'!D37 -> MI | Z24: ='2023 Data'!E37 -> 0.54770906 | AA24: 6 | AB24: ='2023 Data'!N37 -> MI | AC24: ='2023 Data'!O37 -> 0.5 | AE24: 6 | AF24: ='Overall Ranks'!B62 -> RCB | AG24: ='Overall Ranks'!C62 -> 0.4943239 | AH24: 6 | AI24: ='Overall Ranks'!B89 -> PBKS | AJ24: ='Overall Ranks'!C89 -> 0.47880748 | AK24: 6 | AL24: ='Overall Ranks'!B76 -> PBKS | AM24: ='Overall Ranks'!C76 -> 0.51556902
